Workbook

Sheet 主遊戲
A1: 主遊戲
A3: 波輪表 | B3: 波輪表 | C3: 波輪表 | D3: 波輪表 | E3: 波輪表 | F3: 波輪表 | H3: 圖案次數統計 | I3: 圖案次數統計 | J3: 圖案次數統計 | K3: 圖案次數統計 | L3: 圖案次數統計 | M3: 圖案次數統計 | P3: 所有可能數 | Q3: =PRODUCT(I5:M5) -> 3200000
A4: 位置 | B4: 轉輪1 | C4: 轉輪2 | D4: 轉輪3 | E4: 轉輪4 | F4: 轉輪5 | H4: 圖案 | I4: 轉輪1 | J4: 轉輪2 | K4: 轉輪3 | L4: 轉輪4 | M4: 轉輪5
A5: 1 | B5: K | C5: W | D5: W | E5: W | F5: W | H5: any | I5: =COUNTA(B$5:B$24) -> 20 | J5: =COUNTA(C$5:C$24) -> 20 | K5: =COUNTA(D$5:D$24) -> 20 | L5: =COUNTA(E$5:E$24) -> 20 | M5: =COUNTA(F$5:F$24) -> 20 | P5: RTP | Q5: =SUM(Y9:Y39) -> 0.6500425
A6: 2 | B6: Q | C6: K | D6: K | E6: K | F6: K | H6: W | I6: =COUNTIF(B$5:B$24,$H6) -> 0 | J6: =COUNTIF(C$5:C$24,$H6) -> 1 | K6: =COUNTIF(D$5:D$24,$H6) -> 1 | L6: =COUNTIF(E$5:E$24,$H6) -> 1 | M6: =COUNTIF(F$5:F$24,$H6) -> 1
A7: 3 | B7: J | C7: Q | D7: Q | E7: Q | F7: Q | H7: K | I7: =COUNTIF(B$5:B$24,$H7) -> 1 | J7: =COUNTIF(C$5:C$24,$H7) -> 3 | K7: =COUNTIF(D$5:D$24,$H7) -> 3 | L7: =COUNTIF(E$5:E$24,$H7) -> 3 | M7: =COUNTIF(F$5:F$24,$H7) -> 3 | O7: 得分計算表 | P7: 得分計算表 | Q7: 得分計算表 | R7: 得分計算表 | S7: 得分計算表 | T7: 得分計算表 | U7: 得分計算表 | V7: 得分計算表 | W7: 得分計算表 | X7: 得分計算表 | Y7: 得分計算表
A8: 4 | B8: 10 | C8: J | D8: J | E8: J | F8: J | H8: Q | I8: =COUNTIF(B$5:B$24,$H8) -> 3 | J8: =COUNTIF(C$5:C$24,$H8) -> 3 | K8: =COUNTIF(D$5:D$24,$H8) -> 3 | L8: =COUNTIF(E$5:E$24,$H8) -> 3 | M8: =COUNTIF(F$5:F$24,$H8) -> 3 | O8: 圖案 | P8: 連線數 | Q8: 轉輪1 | R8: 轉輪2 | S8: 轉輪3 | T8: 轉輪4 | U8: 轉輪5 | V8: 出現次數 | W8: 出現機率 | X8: 得分數 | Y8: RTP
A9: 5 | B9: 9 | C9: 10 | D9: 10 | E9: 10 | F9: 10 | H9: J | I9: =COUNTIF(B$5:B$24,$H9) -> 4 | J9: =COUNTIF(C$5:C$24,$H9) -> 5 | K9: =COUNTIF(D$5:D$24,$H9) -> 4 | L9: =COUNTIF(E$5:E$24,$H9) -> 4 | M9: =COUNTIF(F$5:F$24,$H9) -> 4 | O9: K | P9: 5 | Q9: WK | R9: WK | S9: WK | T9: WK | U9: WK | V9: =PRODUCT(VLOOKUP(Q9,$H$4:$M$24,2,FALSE),VLOOKUP(R9,$H$4:$M$24,3,FALSE),VLOOKUP(S9,$H$4:$M$24,4,FALSE),VLOOKUP(T9,$H$4:$M$24,5,FALSE),VLOOKUP(U9,$H$4:$M$24,6,FALSE)) -> 256 | W9: =V9/$Q$3 -> 8e-05 | X9: =INDEX($B$30:$D$35,MATCH(O9,$A$30:$A$35,0),MATCH(P9&"連線",$B$29:$D$29,0)) -> 100 | Y9: =W9*X9 -> 0.008
A10: 6 | B10: 9 | C10: 9 | D10: 9 | E10: 9 | F10: 9 | H10: 10 | I10: =COUNTIF(B$5:B$24,$H10) -> 5 | J10: =COUNTIF(C$5:C$24,$H10) -> 3 | K10: =COUNTIF(D$5:D$24,$H10) -> 4 | L10: =COUNTIF(E$5:E$24,$H10) -> 4 | M10: =COUNTIF(F$5:F$24,$H10) -> 4 | O10: K | P10: 4 | Q10: WK | R10: WK | S10: WK | T10: WK | U10: X_WK | V10: =PRODUCT(VLOOKUP(Q10,$H$4:$M$24,2,FALSE),VLOOKUP(R10,$H$4:$M$24,3,FALSE),VLOOKUP(S10,$H$4:$M$24,4,FALSE),VLOOKUP(T10,$H$4:$M$24,5,FALSE),VLOOKUP(U10,$H$4:$M$24,6,FALSE)) -> 1024 | W10: =V10/$Q$3 -> 0.00032 | X10: =INDEX($B$30:$D$35,MATCH(O10,$A$30:$A$35,0),MATCH(P10&"連線",$B$29:$D$29,0)) -> 30 | Y10: =W10*X10 -> 0.0096
A11: 7 | B11: S | C11: S | D11: S | E11: S | F11: S | H11: 9 | I11: =COUNTIF(B$5:B$24,$H11) -> 6 | J11: =COUNTIF(C$5:C$24,$H11) -> 4 | K11: =COUNTIF(D$5:D$24,$H11) -> 4 | L11: =COUNTIF(E$5:E$24,$H11) -> 4 | M11: =COUNTIF(F$5:F$24,$H11) -> 4 | O11: K | P11: 3 | Q11: WK | R11: WK | S11: WK | T11: X_WK | U11: any | V11: =PRODUCT(VLOOKUP(Q11,$H$4:$M$24,2,FALSE),VLOOKUP(R11,$H$4:$M$24,3,FALSE),VLOOKUP(S11,$H$4:$M$24,4,FALSE),VLOOKUP(T11,$H$4:$M$24,5,FALSE),VLOOKUP(U11,$H$4:$M$24,6,FALSE)) -> 5120 | W11: =V11/$Q$3 -> 0.0016 | X11: =INDEX($B$30:$D$35,MATCH(O11,$A$30:$A$35,0),MATCH(P11&"連線",$B$29:$D$29,0)) -> 5 | Y11: =W11*X11 -> 0.008
A12: 8 | B12: Q | C12: K | D12: K | E12: K | F12: K | H12: S | I12: =COUNTIF(B$5:B$24,$H12) -> 1 | J12: =COUNTIF(C$5:C$24,$H12) -> 1 | K12: =COUNTIF(D$5:D$24,$H12) -> 1 | L12: =COUNTIF(E$5:E$24,$H12) -> 1 | M12: =COUNTIF(F$5:F$24,$H12) -> 1 | O12: Q | P12: 5 | Q12: WQ | R12: WQ | S12: WQ | T12: WQ | U12: WQ | V12: =PRODUCT(VLOOKUP(Q12,$H$4:$M$24,2,FALSE),VLOOKUP(R12,$H$4:$M$24,3,FALSE),VLOOKUP(S12,$H$4:$M$24,4,FALSE),VLOOKUP(T12,$H$4:$M$24,5,FALSE),VLOOKUP(U12,$H$4:$M$24,6,FALSE)) -> 768 | W12: =V12/$Q$3 -> 0.00024 | X12: =INDEX($B$30:$D$35,MATCH(O12,$A$30:$A$35,0),MATCH(P12&"連線",$B$29:$D$29,0)) -> 100 | Y12: =W12*X12 -> 0.024
A13: 9 | B13: J | C13: Q | D13: Q | E13: Q | F13: Q | H13: 3S | I13: =I12*3 -> 3 | J13: =J12*3 -> 3 | K13: =K12*3 -> 3 | L13: =L12*3 -> 3 | M13: =M12*3 -> 3 | O13: Q | P13: 4 | Q13: WQ | R13: WQ | S13: WQ | T13: WQ | U13: X_WQ | V13: =PRODUCT(VLOOKUP(Q13,$H$4:$M$24,2,FALSE),VLOOKUP(R13,$H$4:$M$24,3,FALSE),VLOOKUP(S13,$H$4:$M$24,4,FALSE),VLOOKUP(T13,$H$4:$M$24,5,FALSE),VLOOKUP(U13,$H$4:$M$24,6,FALSE)) -> 3072 | W13: =V13/$Q$3 -> 0.00096 | X13: =INDEX($B$30:$D$35,MATCH(O13,$A$30:$A$35,0),MATCH(P13&"連線",$B$29:$D$29,0)) -> 25 | Y13: =W13*X13 -> 0.024
A14: 10 | B14: 10 | C14: J | D14: J | E14: J | F14: J | H14: WK | I14: =I6+I7 -> 1 | J14: =J6+J7 -> 4 | K14: =K6+K7 -> 4 | L14: =L6+L7 -> 4 | M14: =M6+M7 -> 4 | O14: Q | P14: 3 | Q14: WQ | R14: WQ | S14: WQ | T14: X_WQ | U14: any | V14: =PRODUCT(VLOOKUP(Q14,$H$4:$M$24,2,FALSE),VLOOKUP(R14,$H$4:$M$24,3,FALSE),VLOOKUP(S14,$H$4:$M$24,4,FALSE),VLOOKUP(T14,$H$4:$M$24,5,FALSE),VLOOKUP(U14,$H$4:$M$24,6,FALSE)) -> 15360 | W14: =V14/$Q$3 -> 0.0048 | X14: =INDEX($B$30:$D$35,MATCH(O14,$A$30:$A$35,0),MATCH(P14&"連線",$B$29:$D$29,0)) -> 5 | Y14: =W14*X14 -> 0.024
A15: 11 | B15: 9 | C15: 10 | D15: 10 | E15: 10 | F15: 10 | H15: WQ | I15: =I6+I8 -> 3 | J15: =J6+J8 -> 4 | K15: =K6+K8 -> 4 | L15: =L6+L8 -> 4 | M15: =M6+M8 -> 4 | O15: J | P15: 5 | Q15: WJ | R15: WJ | S15: WJ | T15: WJ | U15: WJ | V15: =PRODUCT(VLOOKUP(Q15,$H$4:$M$24,2,FALSE),VLOOKUP(R15,$H$4:$M$24,3,FALSE),VLOOKUP(S15,$H$4:$M$24,4,FALSE),VLOOKUP(T15,$H$4:$M$24,5,FALSE),VLOOKUP(U15,$H$4:$M$24,6,FALSE)) -> 3000 | W15: =V15/$Q$3 -> 0.0009375 | X15: =INDEX($B$30:$D$35,MATCH(O15,$A$30:$A$35,0),MATCH(P15&"連線",$B$29:$D$29,0)) -> 75 | Y15: =W15*X15 -> 0.0703125
A16: 12 | B16: 10 | C16: 9 | D16: 9 | E16: 9 | F16: 9 | H16: WJ | I16: =I6+I9 -> 4 | J16: =J6+J9 -> 6 | K16: =K6+K9 -> 5 | L16: =L6+L9 -> 5 | M16: =M6+M9 -> 5 | O16: J | P16: 4 | Q16: WJ | R16: WJ | S16: WJ | T16: WJ | U16: X_WJ | V16: =PRODUCT(VLOOKUP(Q16,$H$4:$M$24,2,FALSE),VLOOKUP(R16,$H$4:$M$24,3,FALSE),VLOOKUP(S16,$H$4:$M$24,4,FALSE),VLOOKUP(T16,$H$4:$M$24,5,FALSE),VLOOKUP(U16,$H$4:$M$24,6,FALSE)) -> 9000 | W16: =V16/$Q$3 -> 0.0028125 | X16: =INDEX($B$30:$D$35,MATCH(O16,$A$30:$A$35,0),MATCH(P16&"連線",$B$29:$D$29,0)) -> 20 | Y16: =W16*X16 -> 0.05625
A17: 13 | B17: Q | C17: K | D17: K | E17: K | F17: K | H17: W10 | I17: =I6+I10 -> 5 | J17: =J6+J10 -> 4 | K17: =K6+K10 -> 5 | L17: =L6+L10 -> 5 | M17: =M6+M10 -> 5 | O17: J | P17: 3 | Q17: WJ | R17: WJ | S17: WJ | T17: X_WJ | U17: any | V17: =PRODUCT(VLOOKUP(Q17,$H$4:$M$24,2,FALSE),VLOOKUP(R17,$H$4:$M$24,3,FALSE),VLOOKUP(S17,$H$4:$M$24,4,FALSE),VLOOKUP(T17,$H$4:$M$24,5,FALSE),VLOOKUP(U17,$H$4:$M$24,6,FALSE)) -> 36000 | W17: =V17/$Q$3 -> 0.01125 | X17: =INDEX($B$30:$D$35,MATCH(O17,$A$30:$A$35,0),MATCH(P17&"連線",$B$29:$D$29,0)) -> 5 | Y17: =W17*X17 -> 0.05625
A18: 14 | B18: J | C18: Q | D18: Q | E18: Q | F18: Q | H18: W9 | I18: =I6+I11 -> 6 | J18: =J6+J11 -> 5 | K18: =K6+K11 -> 5 | L18: =L6+L11 -> 5 | M18: =M6+M11 -> 5 | O18: 10 | P18: 5 | Q18: W10 | R18: W10 | S18: W10 | T18: W10 | U18: W10 | V18: =PRODUCT(VLOOKUP(Q18,$H$4:$M$24,2,FALSE),VLOOKUP(R18,$H$4:$M$24,3,FALSE),VLOOKUP(S18,$H$4:$M$24,4,FALSE),VLOOKUP(T18,$H$4:$M$24,5,FALSE),VLOOKUP(U18,$H$4:$M$24,6,FALSE)) -> 2500 | W18: =V18/$Q$3 -> 0.00078125 | X18: =INDEX($B$30:$D$35,MATCH(O18,$A$30:$A$35,0),MATCH(P18&"連線",$B$29:$D$29,0)) -> 75 | Y18: =W18*X18 -> 0.05859375
A19: 15 | B19: 10 | C19: J | D19: J | E19: J | F19: J | H19: X_WK | I19: =I5-I14 -> 19 | J19: =J5-J14 -> 16 | K19: =K5-K14 -> 16 | L19: =L5-L14 -> 16 | M19: =M5-M14 -> 16 | O19: 10 | P19: 4 | Q19: W10 | R19: W10 | S19: W10 | T19: W10 | U19: X_W10 | V19: =PRODUCT(VLOOKUP(Q19,$H$4:$M$24,2,FALSE),VLOOKUP(R19,$H$4:$M$24,3,FALSE),VLOOKUP(S19,$H$4:$M$24,4,FALSE),VLOOKUP(T19,$H$4:$M$24,5,FALSE),VLOOKUP(U19,$H$4:$M$24,6,FALSE)) -> 7500 | W19: =V19/$Q$3 -> 0.00234375 | X19: =INDEX($B$30:$D$35,MATCH(O19,$A$30:$A$35,0),MATCH(P19&"連線",$B$29:$D$29,0)) -> 20 | Y19: =W19*X19 -> 0.046875
A20: 16 | B20: 9 | C20: 10 | D20: 10 | E20: 10 | F20: 10 | H20: X_WQ | I20: =I5-I15 -> 17 | J20: =J5-J15 -> 16 | K20: =K5-K15 -> 16 | L20: =L5-L15 -> 16 | M20: =M5-M15 -> 16 | O20: 10 | P20: 3 | Q20: W10 | R20: W10 | S20: W10 | T20: X_W10 | U20: any | V20: =PRODUCT(VLOOKUP(Q20,$H$4:$M$24,2,FALSE),VLOOKUP(R20,$H$4:$M$24,3,FALSE),VLOOKUP(S20,$H$4:$M$24,4,FALSE),VLOOKUP(T20,$H$4:$M$24,5,FALSE),VLOOKUP(U20,$H$4:$M$24,6,FALSE)) -> 30000 | W20: =V20/$Q$3 -> 0.009375 | X20: =INDEX($B$30:$D$35,MATCH(O20,$A$30:$A$35,0),MATCH(P20&"連線",$B$29:$D$29,0)) -> 5 | Y20: =W20*X20 -> 0.046875
A21: 17 | B21: 9 | C21: 9 | D21: 9 | E21: 9 | F21: 9 | H21: X_WJ | I21: =I5-I16 -> 16 | J21: =J5-J16 -> 14 | K21: =K5-K16 -> 15 | L21: =L5-L16 -> 15 | M21: =M5-M16 -> 15 | O21: 9 | P21: 5 | Q21: W9 | R21: W9 | S21: W9 | T21: W9 | U21: W9 | V21: =PRODUCT(VLOOKUP(Q21,$H$4:$M$24,2,FALSE),VLOOKUP(R21,$H$4:$M$24,3,FALSE),VLOOKUP(S21,$H$4:$M$24,4,FALSE),VLOOKUP(T21,$H$4:$M$24,5,FALSE),VLOOKUP(U21,$H$4:$M$24,6,FALSE)) -> 3750 | W21: =V21/$Q$3 -> 0.001171875 | X21: =INDEX($B$30:$D$35,MATCH(O21,$A$30:$A$35,0),MATCH(P21&"連線",$B$29:$D$29,0)) -> 50 | Y21: =W21*X21 -> 0.05859375
A22: 18 | B22: J | C22: J | D22: J | E22: J | F22: J | H22: X_W10 | I22: =I5-I17 -> 15 | J22: =J5-J17 -> 16 | K22: =K5-K17 -> 15 | L22: =L5-L17 -> 15 | M22: =M5-M17 -> 15 | O22: 9 | P22: 4 | Q22: W9 | R22: W9 | S22: W9 | T22: W9 | U22: X_W9 | V22: =PRODUCT(VLOOKUP(Q22,$H$4:$M$24,2,FALSE),VLOOKUP(R22,$H$4:$M$24,3,FALSE),VLOOKUP(S22,$H$4:$M$24,4,FALSE),VLOOKUP(T22,$H$4:$M$24,5,FALSE),VLOOKUP(U22,$H$4:$M$24,6,FALSE)) -> 11250 | W22: =V22/$Q$3 -> 0.003515625 | X22: =INDEX($B$30:$D$35,MATCH(O22,$A$30:$A$35,0),MATCH(P22&"連線",$B$29:$D$29,0)) -> 10 | Y22: =W22*X22 -> 0.03515625
A23: 19 | B23: 10 | C23: J | D23: 10 | E23: 10 | F23: 10 | H23: X_W9 | I23: =I5-I18 -> 14 | J23: =J5-J18 -> 15 | K23: =K5-K18 -> 15 | L23: =L5-L18 -> 15 | M23: =M5-M18 -> 15 | O23: 9 | P23: 3 | Q23: W9 | R23: W9 | S23: W9 | T23: X_W9 | U23: any | V23: =PRODUCT(VLOOKUP(Q23,$H$4:$M$24,2,FALSE),VLOOKUP(R23,$H$4:$M$24,3,FALSE),VLOOKUP(S23,$H$4:$M$24,4,FALSE),VLOOKUP(T23,$H$4:$M$24,5,FALSE),VLOOKUP(U23,$H$4:$M$24,6,FALSE)) -> 45000 | W23: =V23/$Q$3 -> 0.0140625 | X23: =INDEX($B$30:$D$35,MATCH(O23,$A$30:$A$35,0),MATCH(P23&"連線",$B$29:$D$29,0)) -> 5 | Y23: =W23*X23 -> 0.0703125
A24: 20 | B24: 9 | C24: 9 | D24: 9 | E24: 9 | F24: 9 | H24: X_3S | I24: =I5-I13 -> 17 | J24: =J5-J13 -> 17 | K24: =K5-K13 -> 17 | L24: =L5-L13 -> 17 | M24: =M5-M13 -> 17 | O24: S | P24: 3 | Q24: 3S | R24: 3S | S24: 3S | T24: X_3S | U24: X_3S | V24: =PRODUCT(VLOOKUP(Q24,$H$4:$M$24,2,FALSE),VLOOKUP(R24,$H$4:$M$24,3,FALSE),VLOOKUP(S24,$H$4:$M$24,4,FALSE),VLOOKUP(T24,$H$4:$M$24,5,FALSE),VLOOKUP(U24,$H$4:$M$24,6,FALSE)) -> 7803 | W24: =V24/$Q$3 -> 0.0024384375 | X24: =INDEX($B$30:$D$35,MATCH(O24,$A$30:$A$35,0),MATCH(P24&"連線",$B$29:$D$29,0)) -> 2 | Y24: =W24*X24 -> 0.004876875
O25: S | P25: 3 | Q25: 3S | R25: 3S | S25: X_3S | T25: 3S | U25: X_3S | V25: =PRODUCT(VLOOKUP(Q25,$H$4:$M$24,2,FALSE),VLOOKUP(R25,$H$4:$M$24,3,FALSE),VLOOKUP(S25,$H$4:$M$24,4,FALSE),VLOOKUP(T25,$H$4:$M$24,5,FALSE),VLOOKUP(U25,$H$4:$M$24,6,FALSE)) -> 7803 | W25: =V25/$Q$3 -> 0.0024384375 | X25: =INDEX($B$30:$D$35,MATCH(O25,$A$30:$A$35,0),MATCH(P25&"連線",$B$29:$D$29,0)) -> 2 | Y25: =W25*X25 -> 0.004876875
O26: S | P26: 3 | Q26: 3S | R26: 3S | S26: X_3S | T26: X_3S | U26: 3S | V26: =PRODUCT(VLOOKUP(Q26,$H$4:$M$24,2,FALSE),VLOOKUP(R26,$H$4:$M$24,3,FALSE),VLOOKUP(S26,$H$4:$M$24,4,FALSE),VLOOKUP(T26,$H$4:$M$24,5,FALSE),VLOOKUP(U26,$H$4:$M$24,6,FALSE)) -> 7803 | W26: =V26/$Q$3 -> 0.0024384375 | X26: =INDEX($B$30:$D$35,MATCH(O26,$A$30:$A$35,0),MATCH(P26&"連線",$B$29:$D$29,0)) -> 2 | Y26: =W26*X26 -> 0.004876875
O27: S | P27: 3 | Q27: 3S | R27: X_3S | S27: 3S | T27: 3S | U27: X_3S | V27: =PRODUCT(VLOOKUP(Q27,$H$4:$M$24,2,FALSE),VLOOKUP(R27,$H$4:$M$24,3,FALSE),VLOOKUP(S27,$H$4:$M$24,4,FALSE),VLOOKUP(T27,$H$4:$M$24,5,FALSE),VLOOKUP(U27,$H$4:$M$24,6,FALSE)) -> 7803 | W27: =V27/$Q$3 -> 0.0024384375 | X27: =INDEX($B$30:$D$35,MATCH(O27,$A$30:$A$35,0),MATCH(P27&"連線",$B$29:$D$29,0)) -> 2 | Y27: =W27*X27 -> 0.004876875
A28: 賠率表 | B28: 賠率表 | C28: 賠率表 | D28: 賠率表 | E28: 賠率表 | F28: 賠率表 | O28: S | P28: 3 | Q28: 3S | R28: X_3S | S28: 3S | T28: X_3S | U28: 3S | V28: =PRODUCT(VLOOKUP(Q28,$H$4:$M$24,2,FALSE),VLOOKUP(R28,$H$4:$M$24,3,FALSE),VLOOKUP(S28,$H$4:$M$24,4,FALSE),VLOOKUP(T28,$H$4:$M$24,5,FALSE),VLOOKUP(U28,$H$4:$M$24,6,FALSE)) -> 7803 | W28: =V28/$Q$3 -> 0.0024384375 | X28: =INDEX($B$30:$D$35,MATCH(O28,$A$30:$A$35,0),MATCH(P28&"連線",$B$29:$D$29,0)) -> 2 | Y28: =W28*X28 -> 0.004876875
A29: 圖案 | B29: 3連線 | C29: 4連線 | D29: 5連線 | O29: S | P29: 3 | Q29: 3S | R29: X_3S | S29: X_3S | T29: 3S | U29: 3S | V29: =PRODUCT(VLOOKUP(Q29,$H$4:$M$24,2,FALSE),VLOOKUP(R29,$H$4:$M$24,3,FALSE),VLOOKUP(S29,$H$4:$M$24,4,FALSE),VLOOKUP(T29,$H$4:$M$24,5,FALSE),VLOOKUP(U29,$H$4:$M$24,6,FALSE)) -> 7803 | W29: =V29/$Q$3 -> 0.0024384375 | X29: =INDEX($B$30:$D$35,MATCH(O29,$A$30:$A$35,0),MATCH(P29&"連線",$B$29:$D$29,0)) -> 2 | Y29: =W29*X29 -> 0.004876875
A30: K | B30: 5 | C30: 30 | D30: 100 | O30: S | P30: 3 | Q30: X_3S | R30: 3S | S30: 3S | T30: 3S | U30: X_3S | V30: =PRODUCT(VLOOKUP(Q30,$H$4:$M$24,2,FALSE),VLOOKUP(R30,$H$4:$M$24,3,FALSE),VLOOKUP(S30,$H$4:$M$24,4,FALSE),VLOOKUP(T30,$H$4:$M$24,5,FALSE),VLOOKUP(U30,$H$4:$M$24,6,FALSE)) -> 7803 | W30: =V30/$Q$3 -> 0.0024384375 | X30: =INDEX($B$30:$D$35,MATCH(O30,$A$30:$A$35,0),MATCH(P30&"連線",$B$29:$D$29,0)) -> 2 | Y30: =W30*X30 -> 0.004876875
A31: Q | B31: 5 | C31: 25 | D31: 100 | O31: S | P31: 3 | Q31: X_3S | R31: 3S | S31: 3S | T31: X_3S | U31: 3S | V31: =PRODUCT(VLOOKUP(Q31,$H$4:$M$24,2,FALSE),VLOOKUP(R31,$H$4:$M$24,3,FALSE),VLOOKUP(S31,$H$4:$M$24,4,FALSE),VLOOKUP(T31,$H$4:$M$24,5,FALSE),VLOOKUP(U31,$H$4:$M$24,6,FALSE)) -> 7803 | W31: =V31/$Q$3 -> 0.0024384375 | X31: =INDEX($B$30:$D$35,MATCH(O31,$A$30:$A$35,0),MATCH(P31&"連線",$B$29:$D$29,0)) -> 2 | Y31: =W31*X31 -> 0.004876875
A32: J | B32: 5 | C32: 20 | D32: 75 | O32: S | P32: 3 | Q32: X_3S | R32: 3S | S32: X_3S | T32: 3S | U32: 3S | V32: =PRODUCT(VLOOKUP(Q32,$H$4:$M$24,2,FALSE),VLOOKUP(R32,$H$4:$M$24,3,FALSE),VLOOKUP(S32,$H$4:$M$24,4,FALSE),VLOOKUP(T32,$H$4:$M$24,5,FALSE),VLOOKUP(U32,$H$4:$M$24,6,FALSE)) -> 7803 | W32: =V32/$Q$3 -> 0.0024384375 | X32: =INDEX($B$30:$D$35,MATCH(O32,$A$30:$A$35,0),MATCH(P32&"連線",$B$29:$D$29,0)) -> 2 | Y32: =W32*X32 -> 0.004876875
A33: 10 | B33: 5 | C33: 20 | D33: 75 | O33: S | P33: 3 | Q33: X_3S | R33: X_3S | S33: 3S | T33: 3S | U33: 3S | V33: =PRODUCT(VLOOKUP(Q33,$H$4:$M$24,2,FALSE),VLOOKUP(R33,$H$4:$M$24,3,FALSE),VLOOKUP(S33,$H$4:$M$24,4,FALSE),VLOOKUP(T33,$H$4:$M$24,5,FALSE),VLOOKUP(U33,$H$4:$M$24,6,FALSE)) -> 7803 | W33: =V33/$Q$3 -> 0.0024384375 | X33: =INDEX($B$30:$D$35,MATCH(O33,$A$30:$A$35,0),MATCH(P33&"連線",$B$29:$D$29,0)) -> 2 | Y33: =W33*X33 -> 0.004876875
A34: 9 | B34: 5 | C34: 10 | D34: 50 | O34: S | P34: 4 | Q34: 3S | R34: 3S | S34: 3S | T34: 3S | U34: X_3S | V34: =PRODUCT(VLOOKUP(Q34,$H$4:$M$24,2,FALSE),VLOOKUP(R34,$H$4:$M$24,3,FALSE),VLOOKUP(S34,$H$4:$M$24,4,FALSE),VLOOKUP(T34,$H$4:$M$24,5,FALSE),VLOOKUP(U34,$H$4:$M$24,6,FALSE)) -> 1377 | W34: =V34/$Q$3 -> 0.0004303125 | X34: =INDEX($B$30:$D$35,MATCH(O34,$A$30:$A$35,0),MATCH(P34&"連線",$B$29:$D$29,0)) -> 2 | Y34: =W34*X34 -> 0.000860625
A35: S | B35: 2 | C35: 2 | D35: 2 | O35: S | P35: 4 | Q35: 3S | R35: 3S | S35: 3S | T35: X_3S | U35: 3S | V35: =PRODUCT(VLOOKUP(Q35,$H$4:$M$24,2,FALSE),VLOOKUP(R35,$H$4:$M$24,3,FALSE),VLOOKUP(S35,$H$4:$M$24,4,FALSE),VLOOKUP(T35,$H$4:$M$24,5,FALSE),VLOOKUP(U35,$H$4:$M$24,6,FALSE)) -> 1377 | W35: =V35/$Q$3 -> 0.0004303125 | X35: =INDEX($B$30:$D$35,MATCH(O35,$A$30:$A$35,0),MATCH(P35&"連線",$B$29:$D$29,0)) -> 2 | Y35: =W35*X35 -> 0.000860625
O36: S | P36: 4 | Q36: 3S | R36: 3S | S36: X_3S | T36: 3S | U36: 3S | V36: =PRODUCT(VLOOKUP(Q36,$H$4:$M$24,2,FALSE),VLOOKUP(R36,$H$4:$M$24,3,FALSE),VLOOKUP(S36,$H$4:$M$24,4,FALSE),VLOOKUP(T36,$H$4:$M$24,5,FALSE),VLOOKUP(U36,$H$4:$M$24,6,FALSE)) -> 1377 | W36: =V36/$Q$3 -> 0.0004303125 | X36: =INDEX($B$30:$D$35,MATCH(O36,$A$30:$A$35,0),MATCH(P36&"連線",$B$29:$D$29,0)) -> 2 | Y36: =W36*X36 -> 0.000860625
O37: S | P37: 4 | Q37: 3S | R37: X_3S | S37: 3S | T37: 3S | U37: 3S | V37: =PRODUCT(VLOOKUP(Q37,$H$4:$M$24,2,FALSE),VLOOKUP(R37,$H$4:$M$24,3,FALSE),VLOOKUP(S37,$H$4:$M$24,4,FALSE),VLOOKUP(T37,$H$4:$M$24,5,FALSE),VLOOKUP(U37,$H$4:$M$24,6,FALSE)) -> 1377 | W37: =V37/$Q$3 -> 0.0004303125 | X37: =INDEX($B$30:$D$35,MATCH(O37,$A$30:$A$35,0),MATCH(P37&"連線",$B$29:$D$29,0)) -> 2 | Y37: =W37*X37 -> 0.000860625
O38: S | P38: 4 | Q38: X_3S | R38: 3S | S38: 3S | T38: 3S | U38: 3S | V38: =PRODUCT(VLOOKUP(Q38,$H$4:$M$24,2,FALSE),VLOOKUP(R38,$H$4:$M$24,3,FALSE),VLOOKUP(S38,$H$4:$M$24,4,FALSE),VLOOKUP(T38,$H$4:$M$24,5,FALSE),VLOOKUP(U38,$H$4:$M$24,6,FALSE)) -> 1377 | W38: =V38/$Q$3 -> 0.0004303125 | X38: =INDEX($B$30:$D$35,MATCH(O38,$A$30:$A$35,0),MATCH(P38&"連線",$B$29:$D$29,0)) -> 2 | Y38: =W38*X38 -> 0.000860625
O39: S | P39: 5 | Q39: 3S | R39: 3S | S39: 3S | T39: 3S | U39: 3S | V39: =PRODUCT(VLOOKUP(Q39,$H$4:$M$24,2,FALSE),VLOOKUP(R39,$H$4:$M$24,3,FALSE),VLOOKUP(S39,$H$4:$M$24,4,FALSE),VLOOKUP(T39,$H$4:$M$24,5,FALSE),VLOOKUP(U39,$H$4:$M$24,6,FALSE)) -> 243 | W39: =V39/$Q$3 -> 7.59375e-05 | X39: =INDEX($B$30:$D$35,MATCH(O39,$A$30:$A$35,0),MATCH(P39&"連線",$B$29:$D$29,0)) -> 2 | Y39: =W39*X39 -> 0.000151875
H41: Scatter 觸發率摘要 | I41: Scatter 觸發率摘要 | J41: Scatter 觸發率摘要 | K41: Scatter 觸發率摘要 | L41: Scatter 觸發率摘要 | M41: Scatter 觸發率摘要
H42: Scatter 個數 | I42: 3 | J42: 4 | K42: 5 | L42: Total
...

Sheet 免費遊戲
A1: 免費遊戲
A3: 波輪表 | B3: 波輪表 | C3: 波輪表 | D3: 波輪表 | E3: 波輪表 | F3: 波輪表 | H3: 圖案次數統計 | I3: 圖案次數統計 | J3: 圖案次數統計 | K3: 圖案次數統計 | L3: 圖案次數統計 | M3: 圖案次數統計 | P3: 所有可能數 | Q3: =PRODUCT(I5:M5) -> 3040000
A4: 位置 | B4: 轉輪1 | C4: 轉輪2 | D4: 轉輪3 | E4: 轉輪4 | F4: 轉輪5 | H4: 圖案 | I4: 轉輪1 | J4: 轉輪2 | K4: 轉輪3 | L4: 轉輪4 | M4: 轉輪5
A5: 1 | B5: K | C5: W | D5: W | E5: W | F5: W | H5: any | I5: =COUNTA(B$5:B$24) -> 20 | J5: =COUNTA(C$5:C$24) -> 20 | K5: =COUNTA(D$5:D$24) -> 20 | L5: =COUNTA(E$5:E$24) -> 20 | M5: =COUNTA(F$5:F$24) -> 19 | P5: RTP | Q5: =SUM(Y9:Y39) -> 1.0227655
A6: 2 | B6: Q | C6: K | D6: K | E6: K | F6: K | H6: W | I6: =COUNTIF(B$5:B$24,$H6) -> 0 | J6: =COUNTIF(C$5:C$24,$H6) -> 2 | K6: =COUNTIF(D$5:D$24,$H6) -> 2 | L6: =COUNTIF(E$5:E$24,$H6) -> 2 | M6: =COUNTIF(F$5:F$24,$H6) -> 2
A7: 3 | B7: J | C7: Q | D7: Q | E7: Q | F7: Q | H7: K | I7: =COUNTIF(B$5:B$24,$H7) -> 1 | J7: =COUNTIF(C$5:C$24,$H7) -> 3 | K7: =COUNTIF(D$5:D$24,$H7) -> 3 | L7: =COUNTIF(E$5:E$24,$H7) -> 3 | M7: =COUNTIF(F$5:F$24,$H7) -> 3 | O7: 得分計算表 | P7: 得分計算表 | Q7: 得分計算表 | R7: 得分計算表 | S7: 得分計算表 | T7: 得分計算表 | U7: 得分計算表 | V7: 得分計算表 | W7: 得分計算表 | X7: 得分計算表 | Y7: 得分計算表
A8: 4 | B8: 10 | C8: J | D8: J | E8: J | F8: J | H8: Q | I8: =COUNTIF(B$5:B$24,$H8) -> 3 | J8: =COUNTIF(C$5:C$24,$H8) -> 2 | K8: =COUNTIF(D$5:D$24,$H8) -> 2 | L8: =COUNTIF(E$5:E$24,$H8) -> 2 | M8: =COUNTIF(F$5:F$24,$H8) -> 2 | O8: 圖案 | P8: 連線數 | Q8: 轉輪1 | R8: 轉輪2 | S8: 轉輪3 | T8: 轉輪4 | U8: 轉輪5 | V8: 出現次數 | W8: 出現機率 | X8: 得分數 | Y8: RTP
A9: 5 | B9: 9 | C9: 10 | D9: 10 | E9: 10 | F9: 10 | H9: J | I9: =COUNTIF(B$5:B$24,$H9) -> 4 | J9: =COUNTIF(C$5:C$24,$H9) -> 5 | K9: =COUNTIF(D$5:D$24,$H9) -> 4 | L9: =COUNTIF(E$5:E$24,$H9) -> 4 | M9: =COUNTIF(F$5:F$24,$H9) -> 4 | O9: K | P9: 5 | Q9: WK | R9: WK | S9: WK | T9: WK | U9: WK | V9: =PRODUCT(VLOOKUP(Q9,$H$4:$M$24,2,FALSE),VLOOKUP(R9,$H$4:$M$24,3,FALSE),VLOOKUP(S9,$H$4:$M$24,4,FALSE),VLOOKUP(T9,$H$4:$M$24,5,FALSE),VLOOKUP(U9,$H$4:$M$24,6,FALSE)) -> 625 | W9: =V9/$Q$3 -> 0.00020559211 | X9: =INDEX($B$30:$D$35,MATCH(O9,$A$30:$A$35,0),MATCH(P9&"連線",$B$29:$D$29,0)) -> 100 | Y9: =W9*X9 -> 0.020559211
A10: 6 | B10: 9 | C10: 9 | D10: 9 | E10: 9 | F10: 9 | H10: 10 | I10: =COUNTIF(B$5:B$24,$H10) -> 5 | J10: =COUNTIF(C$5:C$24,$H10) -> 3 | K10: =COUNTIF(D$5:D$24,$H10) -> 4 | L10: =COUNTIF(E$5:E$24,$H10) -> 4 | M10: =COUNTIF(F$5:F$24,$H10) -> 4 | O10: K | P10: 4 | Q10: WK | R10: WK | S10: WK | T10: WK | U10: X_WK | V10: =PRODUCT(VLOOKUP(Q10,$H$4:$M$24,2,FALSE),VLOOKUP(R10,$H$4:$M$24,3,FALSE),VLOOKUP(S10,$H$4:$M$24,4,FALSE),VLOOKUP(T10,$H$4:$M$24,5,FALSE),VLOOKUP(U10,$H$4:$M$24,6,FALSE)) -> 1750 | W10: =V10/$Q$3 -> 0.00057565789 | X10: =INDEX($B$30:$D$35,MATCH(O10,$A$30:$A$35,0),MATCH(P10&"連線",$B$29:$D$29,0)) -> 30 | Y10: =W10*X10 -> 0.017269737
A11: 7 | B11: S | C11: S | D11: S | E11: S | F11: S | H11: 9 | I11: =COUNTIF(B$5:B$24,$H11) -> 6 | J11: =COUNTIF(C$5:C$24,$H11) -> 4 | K11: =COUNTIF(D$5:D$24,$H11) -> 4 | L11: =COUNTIF(E$5:E$24,$H11) -> 4 | M11: =COUNTIF(F$5:F$24,$H11) -> 3 | O11: K | P11: 3 | Q11: WK | R11: WK | S11: WK | T11: X_WK | U11: any | V11: =PRODUCT(VLOOKUP(Q11,$H$4:$M$24,2,FALSE),VLOOKUP(R11,$H$4:$M$24,3,FALSE),VLOOKUP(S11,$H$4:$M$24,4,FALSE),VLOOKUP(T11,$H$4:$M$24,5,FALSE),VLOOKUP(U11,$H$4:$M$24,6,FALSE)) -> 7125 | W11: =V11/$Q$3 -> 0.00234375 | X11: =INDEX($B$30:$D$35,MATCH(O11,$A$30:$A$35,0),MATCH(P11&"連線",$B$29:$D$29,0)) -> 5 | Y11: =W11*X11 -> 0.01171875
A12: 8 | B12: Q | C12: K | D12: K | E12: K | F12: K | H12: S | I12: =COUNTIF(B$5:B$24,$H12) -> 1 | J12: =COUNTIF(C$5:C$24,$H12) -> 1 | K12: =COUNTIF(D$5:D$24,$H12) -> 1 | L12: =COUNTIF(E$5:E$24,$H12) -> 1 | M12: =COUNTIF(F$5:F$24,$H12) -> 1 | O12: Q | P12: 5 | Q12: WQ | R12: WQ | S12: WQ | T12: WQ | U12: WQ | V12: =PRODUCT(VLOOKUP(Q12,$H$4:$M$24,2,FALSE),VLOOKUP(R12,$H$4:$M$24,3,FALSE),VLOOKUP(S12,$H$4:$M$24,4,FALSE),VLOOKUP(T12,$H$4:$M$24,5,FALSE),VLOOKUP(U12,$H$4:$M$24,6,FALSE)) -> 768 | W12: =V12/$Q$3 -> 0.00025263158 | X12: =INDEX($B$30:$D$35,MATCH(O12,$A$30:$A$35,0),MATCH(P12&"連線",$B$29:$D$29,0)) -> 100 | Y12: =W12*X12 -> 0.025263158
A13: 9 | B13: J | C13: Q | D13: Q | E13: Q | F13: Q | H13: 3S | I13: =I12*3 -> 3 | J13: =J12*3 -> 3 | K13: =K12*3 -> 3 | L13: =L12*3 -> 3 | M13: =M12*3 -> 3 | O13: Q | P13: 4 | Q13: WQ | R13: WQ | S13: WQ | T13: WQ | U13: X_WQ | V13: =PRODUCT(VLOOKUP(Q13,$H$4:$M$24,2,FALSE),VLOOKUP(R13,$H$4:$M$24,3,FALSE),VLOOKUP(S13,$H$4:$M$24,4,FALSE),VLOOKUP(T13,$H$4:$M$24,5,FALSE),VLOOKUP(U13,$H$4:$M$24,6,FALSE)) -> 2880 | W13: =V13/$Q$3 -> 0.00094736842 | X13: =INDEX($B$30:$D$35,MATCH(O13,$A$30:$A$35,0),MATCH(P13&"連線",$B$29:$D$29,0)) -> 25 | Y13: =W13*X13 -> 0.023684211
A14: 10 | B14: 10 | C14: J | D14: J | E14: J | F14: J | H14: WK | I14: =I6+I7 -> 1 | J14: =J6+J7 -> 5 | K14: =K6+K7 -> 5 | L14: =L6+L7 -> 5 | M14: =M6+M7 -> 5 | O14: Q | P14: 3 | Q14: WQ | R14: WQ | S14: WQ | T14: X_WQ | U14: any | V14: =PRODUCT(VLOOKUP(Q14,$H$4:$M$24,2,FALSE),VLOOKUP(R14,$H$4:$M$24,3,FALSE),VLOOKUP(S14,$H$4:$M$24,4,FALSE),VLOOKUP(T14,$H$4:$M$24,5,FALSE),VLOOKUP(U14,$H$4:$M$24,6,FALSE)) -> 14592 | W14: =V14/$Q$3 -> 0.0048 | X14: =INDEX($B$30:$D$35,MATCH(O14,$A$30:$A$35,0),MATCH(P14&"連線",$B$29:$D$29,0)) -> 5 | Y14: =W14*X14 -> 0.024
A15: 11 | B15: 9 | C15: 10 | D15: 10 | E15: 10 | F15: 10 | H15: WQ | I15: =I6+I8 -> 3 | J15: =J6+J8 -> 4 | K15: =K6+K8 -> 4 | L15: =L6+L8 -> 4 | M15: =M6+M8 -> 4 | O15: J | P15: 5 | Q15: WJ | R15: WJ | S15: WJ | T15: WJ | U15: WJ | V15: =PRODUCT(VLOOKUP(Q15,$H$4:$M$24,2,FALSE),VLOOKUP(R15,$H$4:$M$24,3,FALSE),VLOOKUP(S15,$H$4:$M$24,4,FALSE),VLOOKUP(T15,$H$4:$M$24,5,FALSE),VLOOKUP(U15,$H$4:$M$24,6,FALSE)) -> 6048 | W15: =V15/$Q$3 -> 0.0019894737 | X15: =INDEX($B$30:$D$35,MATCH(O15,$A$30:$A$35,0),MATCH(P15&"連線",$B$29:$D$29,0)) -> 75 | Y15: =W15*X15 -> 0.14921053
A16: 12 | B16: 10 | C16: 9 | D16: 9 | E16: 9 | F16: 9 | H16: WJ | I16: =I6+I9 -> 4 | J16: =J6+J9 -> 7 | K16: =K6+K9 -> 6 | L16: =L6+L9 -> 6 | M16: =M6+M9 -> 6 | O16: J | P16: 4 | Q16: WJ | R16: WJ | S16: WJ | T16: WJ | U16: X_WJ | V16: =PRODUCT(VLOOKUP(Q16,$H$4:$M$24,2,FALSE),VLOOKUP(R16,$H$4:$M$24,3,FALSE),VLOOKUP(S16,$H$4:$M$24,4,FALSE),VLOOKUP(T16,$H$4:$M$24,5,FALSE),VLOOKUP(U16,$H$4:$M$24,6,FALSE)) -> 13104 | W16: =V16/$Q$3 -> 0.0043105263 | X16: =INDEX($B$30:$D$35,MATCH(O16,$A$30:$A$35,0),MATCH(P16&"連線",$B$29:$D$29,0)) -> 20 | Y16: =W16*X16 -> 0.086210526
A17: 13 | B17: Q | C17: K | D17: K | E17: K | F17: K | H17: W10 | I17: =I6+I10 -> 5 | J17: =J6+J10 -> 5 | K17: =K6+K10 -> 6 | L17: =L6+L10 -> 6 | M17: =M6+M10 -> 6 | O17: J | P17: 3 | Q17: WJ | R17: WJ | S17: WJ | T17: X_WJ | U17: any | V17: =PRODUCT(VLOOKUP(Q17,$H$4:$M$24,2,FALSE),VLOOKUP(R17,$H$4:$M$24,3,FALSE),VLOOKUP(S17,$H$4:$M$24,4,FALSE),VLOOKUP(T17,$H$4:$M$24,5,FALSE),VLOOKUP(U17,$H$4:$M$24,6,FALSE)) -> 44688 | W17: =V17/$Q$3 -> 0.0147 | X17: =INDEX($B$30:$D$35,MATCH(O17,$A$30:$A$35,0),MATCH(P17&"連線",$B$29:$D$29,0)) -> 5 | Y17: =W17*X17 -> 0.0735
A18: 14 | B18: J | C18: W | D18: W | E18: W | F18: W | H18: W9 | I18: =I6+I11 -> 6 | J18: =J6+J11 -> 6 | K18: =K6+K11 -> 6 | L18: =L6+L11 -> 6 | M18: =M6+M11 -> 5 | O18: 10 | P18: 5 | Q18: W10 | R18: W10 | S18: W10 | T18: W10 | U18: W10 | V18: =PRODUCT(VLOOKUP(Q18,$H$4:$M$24,2,FALSE),VLOOKUP(R18,$H$4:$M$24,3,FALSE),VLOOKUP(S18,$H$4:$M$24,4,FALSE),VLOOKUP(T18,$H$4:$M$24,5,FALSE),VLOOKUP(U18,$H$4:$M$24,6,FALSE)) -> 5400 | W18: =V18/$Q$3 -> 0.0017763158 | X18: =INDEX($B$30:$D$35,MATCH(O18,$A$30:$A$35,0),MATCH(P18&"連線",$B$29:$D$29,0)) -> 75 | Y18: =W18*X18 -> 0.13322368
A19: 15 | B19: 10 | C19: J | D19: J | E19: J | F19: J | H19: X_WK | I19: =I5-I14 -> 19 | J19: =J5-J14 -> 15 | K19: =K5-K14 -> 15 | L19: =L5-L14 -> 15 | M19: =M5-M14 -> 14 | O19: 10 | P19: 4 | Q19: W10 | R19: W10 | S19: W10 | T19: W10 | U19: X_W10 | V19: =PRODUCT(VLOOKUP(Q19,$H$4:$M$24,2,FALSE),VLOOKUP(R19,$H$4:$M$24,3,FALSE),VLOOKUP(S19,$H$4:$M$24,4,FALSE),VLOOKUP(T19,$H$4:$M$24,5,FALSE),VLOOKUP(U19,$H$4:$M$24,6,FALSE)) -> 11700 | W19: =V19/$Q$3 -> 0.0038486842 | X19: =INDEX($B$30:$D$35,MATCH(O19,$A$30:$A$35,0),MATCH(P19&"連線",$B$29:$D$29,0)) -> 20 | Y19: =W19*X19 -> 0.076973684
A20: 16 | B20: 9 | C20: 10 | D20: 10 | E20: 10 | F20: 10 | H20: X_WQ | I20: =I5-I15 -> 17 | J20: =J5-J15 -> 16 | K20: =K5-K15 -> 16 | L20: =L5-L15 -> 16 | M20: =M5-M15 -> 15 | O20: 10 | P20: 3 | Q20: W10 | R20: W10 | S20: W10 | T20: X_W10 | U20: any | V20: =PRODUCT(VLOOKUP(Q20,$H$4:$M$24,2,FALSE),VLOOKUP(R20,$H$4:$M$24,3,FALSE),VLOOKUP(S20,$H$4:$M$24,4,FALSE),VLOOKUP(T20,$H$4:$M$24,5,FALSE),VLOOKUP(U20,$H$4:$M$24,6,FALSE)) -> 39900 | W20: =V20/$Q$3 -> 0.013125 | X20: =INDEX($B$30:$D$35,MATCH(O20,$A$30:$A$35,0),MATCH(P20&"連線",$B$29:$D$29,0)) -> 5 | Y20: =W20*X20 -> 0.065625
A21: 17 | B21: 9 | C21: 9 | D21: 9 | E21: 9 | F21: 9 | H21: X_WJ | I21: =I5-I16 -> 16 | J21: =J5-J16 -> 13 | K21: =K5-K16 -> 14 | L21: =L5-L16 -> 14 | M21: =M5-M16 -> 13 | O21: 9 | P21: 5 | Q21: W9 | R21: W9 | S21: W9 | T21: W9 | U21: W9 | V21: =PRODUCT(VLOOKUP(Q21,$H$4:$M$24,2,FALSE),VLOOKUP(R21,$H$4:$M$24,3,FALSE),VLOOKUP(S21,$H$4:$M$24,4,FALSE),VLOOKUP(T21,$H$4:$M$24,5,FALSE),VLOOKUP(U21,$H$4:$M$24,6,FALSE)) -> 6480 | W21: =V21/$Q$3 -> 0.0021315789 | X21: =INDEX($B$30:$D$35,MATCH(O21,$A$30:$A$35,0),MATCH(P21&"連線",$B$29:$D$29,0)) -> 50 | Y21: =W21*X21 -> 0.10657895
A22: 18 | B22: J | C22: J | D22: J | E22: J | F22: J | H22: X_W10 | I22: =I5-I17 -> 15 | J22: =J5-J17 -> 15 | K22: =K5-K17 -> 14 | L22: =L5-L17 -> 14 | M22: =M5-M17 -> 13 | O22: 9 | P22: 4 | Q22: W9 | R22: W9 | S22: W9 | T22: W9 | U22: X_W9 | V22: =PRODUCT(VLOOKUP(Q22,$H$4:$M$24,2,FALSE),VLOOKUP(R22,$H$4:$M$24,3,FALSE),VLOOKUP(S22,$H$4:$M$24,4,FALSE),VLOOKUP(T22,$H$4:$M$24,5,FALSE),VLOOKUP(U22,$H$4:$M$24,6,FALSE)) -> 18144 | W22: =V22/$Q$3 -> 0.0059684211 | X22: =INDEX($B$30:$D$35,MATCH(O22,$A$30:$A$35,0),MATCH(P22&"連線",$B$29:$D$29,0)) -> 10 | Y22: =W22*X22 -> 0.059684211
A23: 19 | B23: 10 | C23: J | D23: 10 | E23: 10 | F23: 10 | H23: X_W9 | I23: =I5-I18 -> 14 | J23: =J5-J18 -> 14 | K23: =K5-K18 -> 14 | L23: =L5-L18 -> 14 | M23: =M5-M18 -> 14 | O23: 9 | P23: 3 | Q23: W9 | R23: W9 | S23: W9 | T23: X_W9 | U23: any | V23: =PRODUCT(VLOOKUP(Q23,$H$4:$M$24,2,FALSE),VLOOKUP(R23,$H$4:$M$24,3,FALSE),VLOOKUP(S23,$H$4:$M$24,4,FALSE),VLOOKUP(T23,$H$4:$M$24,5,FALSE),VLOOKUP(U23,$H$4:$M$24,6,FALSE)) -> 57456 | W23: =V23/$Q$3 -> 0.0189 | X23: =INDEX($B$30:$D$35,MATCH(O23,$A$30:$A$35,0),MATCH(P23&"連線",$B$29:$D$29,0)) -> 5 | Y23: =W23*X23 -> 0.0945
A24: 20 | B24: 9 | C24: 9 | D24: 9 | E24: 9 | H24: X_3S | I24: =I5-I13 -> 17 | J24: =J5-J13 -> 17 | K24: =K5-K13 -> 17 | L24: =L5-L13 -> 17 | M24: =M5-M13 -> 16 | O24: S | P24: 3 | Q24: 3S | R24: 3S | S24: 3S | T24: X_3S | U24: X_3S | V24: =PRODUCT(VLOOKUP(Q24,$H$4:$M$24,2,FALSE),VLOOKUP(R24,$H$4:$M$24,3,FALSE),VLOOKUP(S24,$H$4:$M$24,4,FALSE),VLOOKUP(T24,$H$4:$M$24,5,FALSE),VLOOKUP(U24,$H$4:$M$24,6,FALSE)) -> 7344 | W24: =V24/$Q$3 -> 0.0024157895 | X24: =INDEX($B$30:$D$35,MATCH(O24,$A$30:$A$35,0),MATCH(P24&"連線",$B$29:$D$29,0)) -> 2 | Y24: =W24*X24 -> 0.0048315789
O25: S | P25: 3 | Q25: 3S | R25: 3S | S25: X_3S | T25: 3S | U25: X_3S | V25: =PRODUCT(VLOOKUP(Q25,$H$4:$M$24,2,FALSE),VLOOKUP(R25,$H$4:$M$24,3,FALSE),VLOOKUP(S25,$H$4:$M$24,4,FALSE),VLOOKUP(T25,$H$4:$M$24,5,FALSE),VLOOKUP(U25,$H$4:$M$24,6,FALSE)) -> 7344 | W25: =V25/$Q$3 -> 0.0024157895 | X25: =INDEX($B$30:$D$35,MATCH(O25,$A$30:$A$35,0),MATCH(P25&"連線",$B$29:$D$29,0)) -> 2 | Y25: =W25*X25 -> 0.0048315789
O26: S | P26: 3 | Q26: 3S | R26: 3S | S26: X_3S | T26: X_3S | U26: 3S | V26: =PRODUCT(VLOOKUP(Q26,$H$4:$M$24,2,FALSE),VLOOKUP(R26,$H$4:$M$24,3,FALSE),VLOOKUP(S26,$H$4:$M$24,4,FALSE),VLOOKUP(T26,$H$4:$M$24,5,FALSE),VLOOKUP(U26,$H$4:$M$24,6,FALSE)) -> 7803 | W26: =V26/$Q$3 -> 0.0025667763 | X26: =INDEX($B$30:$D$35,MATCH(O26,$A$30:$A$35,0),MATCH(P26&"連線",$B$29:$D$29,0)) -> 2 | Y26: =W26*X26 -> 0.0051335526
H27: 免費遊戲設定 | I27: 免費遊戲設定 | J27: 免費遊戲設定 | K27: 免費遊戲設定 | L27: 免費遊戲設定 | M27: 免費遊戲設定 | O27: S | P27: 3 | Q27: 3S | R27: X_3S | S27: 3S | T27: 3S | U27: X_3S | V27: =PRODUCT(VLOOKUP(Q27,$H$4:$M$24,2,FALSE),VLOOKUP(R27,$H$4:$M$24,3,FALSE),VLOOKUP(S27,$H$4:$M$24,4,FALSE),VLOOKUP(T27,$H$4:$M$24,5,FALSE),VLOOKUP(U27,$H$4:$M$24,6,FALSE)) -> 7344 | W27: =V27/$Q$3 -> 0.0024157895 | X27: =INDEX($B$30:$D$35,MATCH(O27,$A$30:$A$35,0),MATCH(P27&"連線",$B$29:$D$29,0)) -> 2 | Y27: =W27*X27 -> 0.0048315789
A28: 賠率表 | B28: 賠率表 | C28: 賠率表 | D28: 賠率表 | E28: 賠率表 | F28: 賠率表 | H28: Scatter 個數 | I28: 3 | J28: 4 | K28: 5 | O28: S | P28: 3 | Q28: 3S | R28: X_3S | S28: 3S | T28: X_3S | U28: 3S | V28: =PRODUCT(VLOOKUP(Q28,$H$4:$M$24,2,FALSE),VLOOKUP(R28,$H$4:$M$24,3,FALSE),VLOOKUP(S28,$H$4:$M$24,4,FALSE),VLOOKUP(T28,$H$4:$M$24,5,FALSE),VLOOKUP(U28,$H$4:$M$24,6,FALSE)) -> 7803 | W28: =V28/$Q$3 -> 0.0025667763 | X28: =INDEX($B$30:$D$35,MATCH(O28,$A$30:$A$35,0),MATCH(P28&"連線",$B$29:$D$29,0)) -> 2 | Y28: =W28*X28 -> 0.0051335526
A29: 圖案 | B29: 3連線 | C29: 4連線 | D29: 5連線 | H29: 免費遊戲初始次數 | I29: 10 | J29: 15 | K29: 20 | O29: S | P29: 3 | Q29: 3S | R29: X_3S | S29: X_3S | T29: 3S | U29: 3S | V29: =PRODUCT(VLOOKUP(Q29,$H$4:$M$24,2,FALSE),VLOOKUP(R29,$H$4:$M$24,3,FALSE),VLOOKUP(S29,$H$4:$M$24,4,FALSE),VLOOKUP(T29,$H$4:$M$24,5,FALSE),VLOOKUP(U29,$H$4:$M$24,6,FALSE)) -> 7803 | W29: =V29/$Q$3 -> 0.0025667763 | X29: =INDEX($B$30:$D$35,MATCH(O29,$A$30:$A$35,0),MATCH(P29&"連線",$B$29:$D$29,0)) -> 2 | Y29: =W29*X29 -> 0.0051335526
A30: K | B30: 5 | C30: 30 | D30: 100 | H30: 觸發率 | I30: =主遊戲!I43 -> 0.024384375 | J30: =主遊戲!J43 -> 0.0021515625 | K30: =主遊戲!K43 -> 7.59375e-05 | O30: S | P30: 3 | Q30: X_3S | R30: 3S | S30: 3S | T30: 3S | U30: X_3S | V30: =PRODUCT(VLOOKUP(Q30,$H$4:$M$24,2,FALSE),VLOOKUP(R30,$H$4:$M$24,3,FALSE),VLOOKUP(S30,$H$4:$M$24,4,FALSE),VLOOKUP(T30,$H$4:$M$24,5,FALSE),VLOOKUP(U30,$H$4:$M$24,6,FALSE)) -> 7344 | W30: =V30/$Q$3 -> 0.0024157895 | X30: =INDEX($B$30:$D$35,MATCH(O30,$A$30:$A$35,0),MATCH(P30&"連線",$B$29:$D$29,0)) -> 2 | Y30: =W30*X30 -> 0.0048315789
A31: Q | B31: 5 | C31: 25 | D31: 100 | H31: 再觸發率 | I31: =I43 -> 0.025063816 | J31: =J43 -> 0.0022381579 | K31: =K43 -> 7.9934211e-05 | O31: S | P31: 3 | Q31: X_3S | R31: 3S | S31: 3S | T31: X_3S | U31: 3S | V31: =PRODUCT(VLOOKUP(Q31,$H$4:$M$24,2,FALSE),VLOOKUP(R31,$H$4:$M$24,3,FALSE),VLOOKUP(S31,$H$4:$M$24,4,FALSE),VLOOKUP(T31,$H$4:$M$24,5,FALSE),VLOOKUP(U31,$H$4:$M$24,6,FALSE)) -> 7803 | W31: =V31/$Q$3 -> 0.0025667763 | X31: =INDEX($B$30:$D$35,MATCH(O31,$A$30:$A$35,0),MATCH(P31&"連線",$B$29:$D$29,0)) -> 2 | Y31: =W31*X31 -> 0.0051335526
A32: J | B32: 5 | C32: 20 | D32: 75 | H32: 免費遊戲平均總次數 | I32: =I29*$I$34 -> 14.001861 | J32: =J29*$I$34 -> 21.002791 | K32: =K29*$I$34 -> 28.003722 | O32: S | P32: 3 | Q32: X_3S | R32: 3S | S32: X_3S | T32: 3S | U32: 3S | V32: =PRODUCT(VLOOKUP(Q32,$H$4:$M$24,2,FALSE),VLOOKUP(R32,$H$4:$M$24,3,FALSE),VLOOKUP(S32,$H$4:$M$24,4,FALSE),VLOOKUP(T32,$H$4:$M$24,5,FALSE),VLOOKUP(U32,$H$4:$M$24,6,FALSE)) -> 7803 | W32: =V32/$Q$3 -> 0.0025667763 | X32: =INDEX($B$30:$D$35,MATCH(O32,$A$30:$A$35,0),MATCH(P32&"連線",$B$29:$D$29,0)) -> 2 | Y32: =W32*X32 -> 0.0051335526
A33: 10 | B33: 5 | C33: 20 | D33: 75 | H33: RTP | I33: =I30*I32*$Q$5 -> 0.34919936 | J33: =J30*J32*$Q$5 -> 0.046217562 | K33: =K30*K32*$Q$5 -> 0.0021749441 | O33: S | P33: 3 | Q33: X_3S | R33: X_3S | S33: 3S | T33: 3S | U33: 3S | V33: =PRODUCT(VLOOKUP(Q33,$H$4:$M$24,2,FALSE),VLOOKUP(R33,$H$4:$M$24,3,FALSE),VLOOKUP(S33,$H$4:$M$24,4,FALSE),VLOOKUP(T33,$H$4:$M$24,5,FALSE),VLOOKUP(U33,$H$4:$M$24,6,FALSE)) -> 7803 | W33: =V33/$Q$3 -> 0.0025667763 | X33: =INDEX($B$30:$D$35,MATCH(O33,$A$30:$A$35,0),MATCH(P33&"連線",$B$29:$D$29,0)) -> 2 | Y33: =W33*X33 -> 0.0051335526
A34: 9 | B34: 5 | C34: 10 | D34: 50 | H34: 免費遊戲1個Spin、含再觸發後的平均Spins數 | I34: =1/(1-SUMPRODUCT(I31:K31,I29:K29)) -> 1.4001861 | O34: S | P34: 4 | Q34: 3S | R34: 3S | S34: 3S | T34: 3S | U34: X_3S | V34: =PRODUCT(VLOOKUP(Q34,$H$4:$M$24,2,FALSE),VLOOKUP(R34,$H$4:$M$24,3,FALSE),VLOOKUP(S34,$H$4:$M$24,4,FALSE),VLOOKUP(T34,$H$4:$M$24,5,FALSE),VLOOKUP(U34,$H$4:$M$24,6,FALSE)) -> 1296 | W34: =V34/$Q$3 -> 0.00042631579 | X34: =INDEX($B$30:$D$35,MATCH(O34,$A$30:$A$35,0),MATCH(P34&"連線",$B$29:$D$29,0)) -> 2 | Y34: =W34*X34 -> 0.00085263158
A35: S | B35: 2 | C35: 2 | D35: 2 | O35: S | P35: 4 | Q35: 3S | R35: 3S | S35: 3S | T35: X_3S | U35: 3S | V35: =PRODUCT(VLOOKUP(Q35,$H$4:$M$24,2,FALSE),VLOOKUP(R35,$H$4:$M$24,3,FALSE),VLOOKUP(S35,$H$4:$M$24,4,FALSE),VLOOKUP(T35,$H$4:$M$24,5,FALSE),VLOOKUP(U35,$H$4:$M$24,6,FALSE)) -> 1377 | W35: =V35/$Q$3 -> 0.00045296053 | X35: =INDEX($B$30:$D$35,MATCH(O35,$A$30:$A$35,0),MATCH(P35&"連線",$B$29:$D$29,0)) -> 2 | Y35: =W35*X35 -> 0.00090592105
O36: S | P36: 4 | Q36: 3S | R36: 3S | S36: X_3S | T36: 3S | U36: 3S | V36: =PRODUCT(VLOOKUP(Q36,$H$4:$M$24,2,FALSE),VLOOKUP(R36,$H$4:$M$24,3,FALSE),VLOOKUP(S36,$H$4:$M$24,4,FALSE),VLOOKUP(T36,$H$4:$M$24,5,FALSE),VLOOKUP(U36,$H$4:$M$24,6,FALSE)) -> 1377 | W36: =V36/$Q$3 -> 0.00045296053 | X36: =INDEX($B$30:$D$35,MATCH(O36,$A$30:$A$35,0),MATCH(P36&"連線",$B$29:$D$29,0)) -> 2 | Y36: =W36*X36 -> 0.00090592105
O37: S | P37: 4 | Q37: 3S | R37: X_3S | S37: 3S | T37: 3S | U37: 3S | V37: =PRODUCT(VLOOKUP(Q37,$H$4:$M$24,2,FALSE),VLOOKUP(R37,$H$4:$M$24,3,FALSE),VLOOKUP(S37,$H$4:$M$24,4,FALSE),VLOOKUP(T37,$H$4:$M$24,5,FALSE),VLOOKUP(U37,$H$4:$M$24,6,FALSE)) -> 1377 | W37: =V37/$Q$3 -> 0.00045296053 | X37: =INDEX($B$30:$D$35,MATCH(O37,$A$30:$A$35,0),MATCH(P37&"連線",$B$29:$D$29,0)) -> 2 | Y37: =W37*X37 -> 0.00090592105
O38: S | P38: 4 | Q38: X_3S | R38: 3S | S38: 3S | T38: 3S | U38: 3S | V38: =PRODUCT(VLOOKUP(Q38,$H$4:$M$24,2,FALSE),VLOOKUP(R38,$H$4:$M$24,3,FALSE),VLOOKUP(S38,$H$4:$M$24,4,FALSE),VLOOKUP(T38,$H$4:$M$24,5,FALSE),VLOOKUP(U38,$H$4:$M$24,6,FALSE)) -> 1377 | W38: =V38/$Q$3 -> 0.00045296053 | X38: =INDEX($B$30:$D$35,MATCH(O38,$A$30:$A$35,0),MATCH(P38&"連線",$B$29:$D$29,0)) -> 2 | Y38: =W38*X38 -> 0.00090592105
O39: S | P39: 5 | Q39: 3S | R39: 3S | S39: 3S | T39: 3S | U39: 3S | V39: =PRODUCT(VLOOKUP(Q39,$H$4:$M$24,2,FALSE),VLOOKUP(R39,$H$4:$M$24,3,FALSE),VLOOKUP(S39,$H$4:$M$24,4,FALSE),VLOOKUP(T39,$H$4:$M$24,5,FALSE),VLOOKUP(U39,$H$4:$M$24,6,FALSE)) -> 243 | W39: =V39/$Q$3 -> 7.9934211e-05 | X39: =INDEX($B$30:$D$35,MATCH(O39,$A$30:$A$35,0),MATCH(P39&"連線",$B$29:$D$29,0)) -> 2 | Y39: =W39*X39 -> 0.00015986842
H41: Scatter 觸發率摘要 | I41: Scatter 觸發率摘要 | J41: Scatter 觸發率摘要 | K41: Scatter 觸發率摘要 | L41: Scatter 觸發率摘要 | M41: Scatter 觸發率摘要
H42: Scatter 個數 | I42: 3 | J42: 4 | K42: 5 | L42: Total
...

Sheet Summary
A1: PART II RTP Summary
A3: Free Game RTP | B3: 3 Scatter | C3: 4 Scatter | D3: 5 Scatter | E3: Total
A4: Contribution | B4: =免費遊戲!I33 -> 0.34919936 | C4: =免費遊戲!J33 -> 0.046217562 | D4: =免費遊戲!K33 -> 0.0021749441 | E4: =SUM(B4:D4) -> 0.39759186
A6: Formula
A7: Free Game RTP = 34.92% + 4.62% + 0.22% = 39.76%
A10: Total RTP | B10: Value | C10: Formula
A11: Main Game RTP | B11: =主遊戲!Q5 -> 0.6500425 | C11: from 主遊戲!Q5
A12: Free Game RTP | B12: =E4 -> 0.39759186 | C12: 34.92% + 4.62% + 0.22%
A13: Total RTP | B13: =B11+B12 -> 1.0476344 | C13: Main Game RTP + Free Game RTP
