Workbook

Sheet Sticky Wild
A1: 黏性百搭 Sticky Wild - State Probability
A2: Source: https://ezslotdesign.com/stickywild/
B4: 滾輪表 | H4: State Probability：Free Spin #1~10 開始時
B5: R1 | C5: R2 | D5: R3 | E5: R4 | F5: R5 | H5: WILD Status | I5: R1 | J5: R2 | K5: R3 | L5: R4 | M5: R5 | N5: 1 | O5: 2 | P5: 3 | Q5: 4 | R5: 5 | S5: 6 | T5: 7 | U5: 8 | V5: 9 | W5: 10
A6: 1 | B6: WILD | C6: WILD | D6: WILD | E6: WILD | F6: WILD | H6: 0 | N6: =IF($I6="W",1-$B$25^(N$5-1),$B$25^(N$5-1))*IF($J6="W",1-$C$25^(N$5-1),$C$25^(N$5-1))*IF($K6="W",1-$D$25^(N$5-1),$D$25^(N$5-1))*IF($L6="W",1-$E$25^(N$5-1),$E$25^(N$5-1))*IF($M6="W",1-$F$25^(N$5-1),$F$25^(N$5-1)) -> 1 | O6: =IF($I6="W",1-$B$25^(O$5-1),$B$25^(O$5-1))*IF($J6="W",1-$C$25^(O$5-1),$C$25^(O$5-1))*IF($K6="W",1-$D$25^(O$5-1),$D$25^(O$5-1))*IF($L6="W",1-$E$25^(O$5-1),$E$25^(O$5-1))*IF($M6="W",1-$F$25^(O$5-1),$F$25^(O$5-1)) -> 0.6875 | P6: =IF($I6="W",1-$B$25^(P$5-1),$B$25^(P$5-1))*IF($J6="W",1-$C$25^(P$5-1),$C$25^(P$5-1))*IF($K6="W",1-$D$25^(P$5-1),$D$25^(P$5-1))*IF($L6="W",1-$E$25^(P$5-1),$E$25^(P$5-1))*IF($M6="W",1-$F$25^(P$5-1),$F$25^(P$5-1)) -> 0.47265625 | Q6: =IF($I6="W",1-$B$25^(Q$5-1),$B$25^(Q$5-1))*IF($J6="W",1-$C$25^(Q$5-1),$C$25^(Q$5-1))*IF($K6="W",1-$D$25^(Q$5-1),$D$25^(Q$5-1))*IF($L6="W",1-$E$25^(Q$5-1),$E$25^(Q$5-1))*IF($M6="W",1-$F$25^(Q$5-1),$F$25^(Q$5-1)) -> 0.32495117 | R6: =IF($I6="W",1-$B$25^(R$5-1),$B$25^(R$5-1))*IF($J6="W",1-$C$25^(R$5-1),$C$25^(R$5-1))*IF($K6="W",1-$D$25^(R$5-1),$D$25^(R$5-1))*IF($L6="W",1-$E$25^(R$5-1),$E$25^(R$5-1))*IF($M6="W",1-$F$25^(R$5-1),$F$25^(R$5-1)) -> 0.22340393 | S6: =IF($I6="W",1-$B$25^(S$5-1),$B$25^(S$5-1))*IF($J6="W",1-$C$25^(S$5-1),$C$25^(S$5-1))*IF($K6="W",1-$D$25^(S$5-1),$D$25^(S$5-1))*IF($L6="W",1-$E$25^(S$5-1),$E$25^(S$5-1))*IF($M6="W",1-$F$25^(S$5-1),$F$25^(S$5-1)) -> 0.1535902 | T6: =IF($I6="W",1-$B$25^(T$5-1),$B$25^(T$5-1))*IF($J6="W",1-$C$25^(T$5-1),$C$25^(T$5-1))*IF($K6="W",1-$D$25^(T$5-1),$D$25^(T$5-1))*IF($L6="W",1-$E$25^(T$5-1),$E$25^(T$5-1))*IF($M6="W",1-$F$25^(T$5-1),$F$25^(T$5-1)) -> 0.10559326 | U6: =IF($I6="W",1-$B$25^(U$5-1),$B$25^(U$5-1))*IF($J6="W",1-$C$25^(U$5-1),$C$25^(U$5-1))*IF($K6="W",1-$D$25^(U$5-1),$D$25^(U$5-1))*IF($L6="W",1-$E$25^(U$5-1),$E$25^(U$5-1))*IF($M6="W",1-$F$25^(U$5-1),$F$25^(U$5-1)) -> 0.072595369 | ... W6: =IF($I6="W",1-$B$25^(W$5-1),$B$25^(W$5-1))*IF($J6="W",1-$C$25^(W$5-1),$C$25^(W$5-1))*IF($K6="W",1-$D$25^(W$5-1),$D$25^(W$5-1))*IF($L6="W",1-$E$25^(W$5-1),$E$25^(W$5-1))*IF($M6="W",1-$F$25^(W$5-1),$F$25^(W$5-1)) -> 0.034312655
A7: 2 | B7: A | C7: A | D7: A | E7: A | F7: A | H7: 1 | M7: W | N7: =IF($I7="W",1-$B$25^(N$5-1),$B$25^(N$5-1))*IF($J7="W",1-$C$25^(N$5-1),$C$25^(N$5-1))*IF($K7="W",1-$D$25^(N$5-1),$D$25^(N$5-1))*IF($L7="W",1-$E$25^(N$5-1),$E$25^(N$5-1))*IF($M7="W",1-$F$25^(N$5-1),$F$25^(N$5-1)) -> 0 | O7: =IF($I7="W",1-$B$25^(O$5-1),$B$25^(O$5-1))*IF($J7="W",1-$C$25^(O$5-1),$C$25^(O$5-1))*IF($K7="W",1-$D$25^(O$5-1),$D$25^(O$5-1))*IF($L7="W",1-$E$25^(O$5-1),$E$25^(O$5-1))*IF($M7="W",1-$F$25^(O$5-1),$F$25^(O$5-1)) -> 0.0625 | P7: =IF($I7="W",1-$B$25^(P$5-1),$B$25^(P$5-1))*IF($J7="W",1-$C$25^(P$5-1),$C$25^(P$5-1))*IF($K7="W",1-$D$25^(P$5-1),$D$25^(P$5-1))*IF($L7="W",1-$E$25^(P$5-1),$E$25^(P$5-1))*IF($M7="W",1-$F$25^(P$5-1),$F$25^(P$5-1)) -> 0.08984375 | Q7: =IF($I7="W",1-$B$25^(Q$5-1),$B$25^(Q$5-1))*IF($J7="W",1-$C$25^(Q$5-1),$C$25^(Q$5-1))*IF($K7="W",1-$D$25^(Q$5-1),$D$25^(Q$5-1))*IF($L7="W",1-$E$25^(Q$5-1),$E$25^(Q$5-1))*IF($M7="W",1-$F$25^(Q$5-1),$F$25^(Q$5-1)) -> 0.096923828 | R7: =IF($I7="W",1-$B$25^(R$5-1),$B$25^(R$5-1))*IF($J7="W",1-$C$25^(R$5-1),$C$25^(R$5-1))*IF($K7="W",1-$D$25^(R$5-1),$D$25^(R$5-1))*IF($L7="W",1-$E$25^(R$5-1),$E$25^(R$5-1))*IF($M7="W",1-$F$25^(R$5-1),$F$25^(R$5-1)) -> 0.093002319 | S7: =IF($I7="W",1-$B$25^(S$5-1),$B$25^(S$5-1))*IF($J7="W",1-$C$25^(S$5-1),$C$25^(S$5-1))*IF($K7="W",1-$D$25^(S$5-1),$D$25^(S$5-1))*IF($L7="W",1-$E$25^(S$5-1),$E$25^(S$5-1))*IF($M7="W",1-$F$25^(S$5-1),$F$25^(S$5-1)) -> 0.083714485 | T7: =IF($I7="W",1-$B$25^(T$5-1),$B$25^(T$5-1))*IF($J7="W",1-$C$25^(T$5-1),$C$25^(T$5-1))*IF($K7="W",1-$D$25^(T$5-1),$D$25^(T$5-1))*IF($L7="W",1-$E$25^(T$5-1),$E$25^(T$5-1))*IF($M7="W",1-$F$25^(T$5-1),$F$25^(T$5-1)) -> 0.072385252 | U7: =IF($I7="W",1-$B$25^(U$5-1),$B$25^(U$5-1))*IF($J7="W",1-$C$25^(U$5-1),$C$25^(U$5-1))*IF($K7="W",1-$D$25^(U$5-1),$D$25^(U$5-1))*IF($L7="W",1-$E$25^(U$5-1),$E$25^(U$5-1))*IF($M7="W",1-$F$25^(U$5-1),$F$25^(U$5-1)) -> 0.060888518 | ... W7: =IF($I7="W",1-$B$25^(W$5-1),$B$25^(W$5-1))*IF($J7="W",1-$C$25^(W$5-1),$C$25^(W$5-1))*IF($K7="W",1-$D$25^(W$5-1),$D$25^(W$5-1))*IF($L7="W",1-$E$25^(W$5-1),$E$25^(W$5-1))*IF($M7="W",1-$F$25^(W$5-1),$F$25^(W$5-1)) -> 0.040772031
A8: 3 | B8: K | C8: K | D8: K | E8: K | F8: K | H8: 2 | L8: W | N8: =IF($I8="W",1-$B$25^(N$5-1),$B$25^(N$5-1))*IF($J8="W",1-$C$25^(N$5-1),$C$25^(N$5-1))*IF($K8="W",1-$D$25^(N$5-1),$D$25^(N$5-1))*IF($L8="W",1-$E$25^(N$5-1),$E$25^(N$5-1))*IF($M8="W",1-$F$25^(N$5-1),$F$25^(N$5-1)) -> 0 | O8: =IF($I8="W",1-$B$25^(O$5-1),$B$25^(O$5-1))*IF($J8="W",1-$C$25^(O$5-1),$C$25^(O$5-1))*IF($K8="W",1-$D$25^(O$5-1),$D$25^(O$5-1))*IF($L8="W",1-$E$25^(O$5-1),$E$25^(O$5-1))*IF($M8="W",1-$F$25^(O$5-1),$F$25^(O$5-1)) -> 0.057291667 | P8: =IF($I8="W",1-$B$25^(P$5-1),$B$25^(P$5-1))*IF($J8="W",1-$C$25^(P$5-1),$C$25^(P$5-1))*IF($K8="W",1-$D$25^(P$5-1),$D$25^(P$5-1))*IF($L8="W",1-$E$25^(P$5-1),$E$25^(P$5-1))*IF($M8="W",1-$F$25^(P$5-1),$F$25^(P$5-1)) -> 0.082058377 | Q8: =IF($I8="W",1-$B$25^(Q$5-1),$B$25^(Q$5-1))*IF($J8="W",1-$C$25^(Q$5-1),$C$25^(Q$5-1))*IF($K8="W",1-$D$25^(Q$5-1),$D$25^(Q$5-1))*IF($L8="W",1-$E$25^(Q$5-1),$E$25^(Q$5-1))*IF($M8="W",1-$F$25^(Q$5-1),$F$25^(Q$5-1)) -> 0.088195659 | R8: =IF($I8="W",1-$B$25^(R$5-1),$B$25^(R$5-1))*IF($J8="W",1-$C$25^(R$5-1),$C$25^(R$5-1))*IF($K8="W",1-$D$25^(R$5-1),$D$25^(R$5-1))*IF($L8="W",1-$E$25^(R$5-1),$E$25^(R$5-1))*IF($M8="W",1-$F$25^(R$5-1),$F$25^(R$5-1)) -> 0.084304386 | S8: =IF($I8="W",1-$B$25^(S$5-1),$B$25^(S$5-1))*IF($J8="W",1-$C$25^(S$5-1),$C$25^(S$5-1))*IF($K8="W",1-$D$25^(S$5-1),$D$25^(S$5-1))*IF($L8="W",1-$E$25^(S$5-1),$E$25^(S$5-1))*IF($M8="W",1-$F$25^(S$5-1),$F$25^(S$5-1)) -> 0.075588388 | T8: =IF($I8="W",1-$B$25^(T$5-1),$B$25^(T$5-1))*IF($J8="W",1-$C$25^(T$5-1),$C$25^(T$5-1))*IF($K8="W",1-$D$25^(T$5-1),$D$25^(T$5-1))*IF($L8="W",1-$E$25^(T$5-1),$E$25^(T$5-1))*IF($M8="W",1-$F$25^(T$5-1),$F$25^(T$5-1)) -> 0.06509704 | U8: =IF($I8="W",1-$B$25^(U$5-1),$B$25^(U$5-1))*IF($J8="W",1-$C$25^(U$5-1),$C$25^(U$5-1))*IF($K8="W",1-$D$25^(U$5-1),$D$25^(U$5-1))*IF($L8="W",1-$E$25^(U$5-1),$E$25^(U$5-1))*IF($M8="W",1-$F$25^(U$5-1),$F$25^(U$5-1)) -> 0.054533347 | ... W8: =IF($I8="W",1-$B$25^(W$5-1),$B$25^(W$5-1))*IF($J8="W",1-$C$25^(W$5-1),$C$25^(W$5-1))*IF($K8="W",1-$D$25^(W$5-1),$D$25^(W$5-1))*IF($L8="W",1-$E$25^(W$5-1),$E$25^(W$5-1))*IF($M8="W",1-$F$25^(W$5-1),$F$25^(W$5-1)) -> 0.036207503
A9: 4 | B9: Q | C9: Q | D9: Q | E9: Q | F9: Q | H9: 3 | L9: W | M9: W | N9: =IF($I9="W",1-$B$25^(N$5-1),$B$25^(N$5-1))*IF($J9="W",1-$C$25^(N$5-1),$C$25^(N$5-1))*IF($K9="W",1-$D$25^(N$5-1),$D$25^(N$5-1))*IF($L9="W",1-$E$25^(N$5-1),$E$25^(N$5-1))*IF($M9="W",1-$F$25^(N$5-1),$F$25^(N$5-1)) -> 0 | O9: =IF($I9="W",1-$B$25^(O$5-1),$B$25^(O$5-1))*IF($J9="W",1-$C$25^(O$5-1),$C$25^(O$5-1))*IF($K9="W",1-$D$25^(O$5-1),$D$25^(O$5-1))*IF($L9="W",1-$E$25^(O$5-1),$E$25^(O$5-1))*IF($M9="W",1-$F$25^(O$5-1),$F$25^(O$5-1)) -> 0.0052083333 | P9: =IF($I9="W",1-$B$25^(P$5-1),$B$25^(P$5-1))*IF($J9="W",1-$C$25^(P$5-1),$C$25^(P$5-1))*IF($K9="W",1-$D$25^(P$5-1),$D$25^(P$5-1))*IF($L9="W",1-$E$25^(P$5-1),$E$25^(P$5-1))*IF($M9="W",1-$F$25^(P$5-1),$F$25^(P$5-1)) -> 0.015597873 | Q9: =IF($I9="W",1-$B$25^(Q$5-1),$B$25^(Q$5-1))*IF($J9="W",1-$C$25^(Q$5-1),$C$25^(Q$5-1))*IF($K9="W",1-$D$25^(Q$5-1),$D$25^(Q$5-1))*IF($L9="W",1-$E$25^(Q$5-1),$E$25^(Q$5-1))*IF($M9="W",1-$F$25^(Q$5-1),$F$25^(Q$5-1)) -> 0.026306294 | R9: =IF($I9="W",1-$B$25^(R$5-1),$B$25^(R$5-1))*IF($J9="W",1-$C$25^(R$5-1),$C$25^(R$5-1))*IF($K9="W",1-$D$25^(R$5-1),$D$25^(R$5-1))*IF($L9="W",1-$E$25^(R$5-1),$E$25^(R$5-1))*IF($M9="W",1-$F$25^(R$5-1),$F$25^(R$5-1)) -> 0.035095638 | S9: =IF($I9="W",1-$B$25^(S$5-1),$B$25^(S$5-1))*IF($J9="W",1-$C$25^(S$5-1),$C$25^(S$5-1))*IF($K9="W",1-$D$25^(S$5-1),$D$25^(S$5-1))*IF($L9="W",1-$E$25^(S$5-1),$E$25^(S$5-1))*IF($M9="W",1-$F$25^(S$5-1),$F$25^(S$5-1)) -> 0.041199522 | T9: =IF($I9="W",1-$B$25^(T$5-1),$B$25^(T$5-1))*IF($J9="W",1-$C$25^(T$5-1),$C$25^(T$5-1))*IF($K9="W",1-$D$25^(T$5-1),$D$25^(T$5-1))*IF($L9="W",1-$E$25^(T$5-1),$E$25^(T$5-1))*IF($M9="W",1-$F$25^(T$5-1),$F$25^(T$5-1)) -> 0.04462468 | U9: =IF($I9="W",1-$B$25^(U$5-1),$B$25^(U$5-1))*IF($J9="W",1-$C$25^(U$5-1),$C$25^(U$5-1))*IF($K9="W",1-$D$25^(U$5-1),$D$25^(U$5-1))*IF($L9="W",1-$E$25^(U$5-1),$E$25^(U$5-1))*IF($M9="W",1-$F$25^(U$5-1),$F$25^(U$5-1)) -> 0.045739208 | ... W9: =IF($I9="W",1-$B$25^(W$5-1),$B$25^(W$5-1))*IF($J9="W",1-$C$25^(W$5-1),$C$25^(W$5-1))*IF($K9="W",1-$D$25^(W$5-1),$D$25^(W$5-1))*IF($L9="W",1-$E$25^(W$5-1),$E$25^(W$5-1))*IF($M9="W",1-$F$25^(W$5-1),$F$25^(W$5-1)) -> 0.043023586
A10: 5 | B10: J | C10: J | D10: J | E10: J | F10: J | H10: 4 | K10: W | N10: =IF($I10="W",1-$B$25^(N$5-1),$B$25^(N$5-1))*IF($J10="W",1-$C$25^(N$5-1),$C$25^(N$5-1))*IF($K10="W",1-$D$25^(N$5-1),$D$25^(N$5-1))*IF($L10="W",1-$E$25^(N$5-1),$E$25^(N$5-1))*IF($M10="W",1-$F$25^(N$5-1),$F$25^(N$5-1)) -> 0 | O10: =IF($I10="W",1-$B$25^(O$5-1),$B$25^(O$5-1))*IF($J10="W",1-$C$25^(O$5-1),$C$25^(O$5-1))*IF($K10="W",1-$D$25^(O$5-1),$D$25^(O$5-1))*IF($L10="W",1-$E$25^(O$5-1),$E$25^(O$5-1))*IF($M10="W",1-$F$25^(O$5-1),$F$25^(O$5-1)) -> 0.052884615 | P10: =IF($I10="W",1-$B$25^(P$5-1),$B$25^(P$5-1))*IF($J10="W",1-$C$25^(P$5-1),$C$25^(P$5-1))*IF($K10="W",1-$D$25^(P$5-1),$D$25^(P$5-1))*IF($L10="W",1-$E$25^(P$5-1),$E$25^(P$5-1))*IF($M10="W",1-$F$25^(P$5-1),$F$25^(P$5-1)) -> 0.075513129 | Q10: =IF($I10="W",1-$B$25^(Q$5-1),$B$25^(Q$5-1))*IF($J10="W",1-$C$25^(Q$5-1),$C$25^(Q$5-1))*IF($K10="W",1-$D$25^(Q$5-1),$D$25^(Q$5-1))*IF($L10="W",1-$E$25^(Q$5-1),$E$25^(Q$5-1))*IF($M10="W",1-$F$25^(Q$5-1),$F$25^(Q$5-1)) -> 0.080905003 | R10: =IF($I10="W",1-$B$25^(R$5-1),$B$25^(R$5-1))*IF($J10="W",1-$C$25^(R$5-1),$C$25^(R$5-1))*IF($K10="W",1-$D$25^(R$5-1),$D$25^(R$5-1))*IF($L10="W",1-$E$25^(R$5-1),$E$25^(R$5-1))*IF($M10="W",1-$F$25^(R$5-1),$F$25^(R$5-1)) -> 0.077085737 | S10: =IF($I10="W",1-$B$25^(S$5-1),$B$25^(S$5-1))*IF($J10="W",1-$C$25^(S$5-1),$C$25^(S$5-1))*IF($K10="W",1-$D$25^(S$5-1),$D$25^(S$5-1))*IF($L10="W",1-$E$25^(S$5-1),$E$25^(S$5-1))*IF($M10="W",1-$F$25^(S$5-1),$F$25^(S$5-1)) -> 0.068887725 | T10: =IF($I10="W",1-$B$25^(T$5-1),$B$25^(T$5-1))*IF($J10="W",1-$C$25^(T$5-1),$C$25^(T$5-1))*IF($K10="W",1-$D$25^(T$5-1),$D$25^(T$5-1))*IF($L10="W",1-$E$25^(T$5-1),$E$25^(T$5-1))*IF($M10="W",1-$F$25^(T$5-1),$F$25^(T$5-1)) -> 0.05912597 | U10: =IF($I10="W",1-$B$25^(U$5-1),$B$25^(U$5-1))*IF($J10="W",1-$C$25^(U$5-1),$C$25^(U$5-1))*IF($K10="W",1-$D$25^(U$5-1),$D$25^(U$5-1))*IF($L10="W",1-$E$25^(U$5-1),$E$25^(U$5-1))*IF($M10="W",1-$F$25^(U$5-1),$F$25^(U$5-1)) -> 0.049360218 | ... W10: =IF($I10="W",1-$B$25^(W$5-1),$B$25^(W$5-1))*IF($J10="W",1-$C$25^(W$5-1),$C$25^(W$5-1))*IF($K10="W",1-$D$25^(W$5-1),$D$25^(W$5-1))*IF($L10="W",1-$E$25^(W$5-1),$E$25^(W$5-1))*IF($M10="W",1-$F$25^(W$5-1),$F$25^(W$5-1)) -> 0.032539663
A11: 6 | B11: 10 | C11: 10 | D11: 10 | E11: 10 | F11: 10 | H11: 5 | K11: W | M11: W | N11: =IF($I11="W",1-$B$25^(N$5-1),$B$25^(N$5-1))*IF($J11="W",1-$C$25^(N$5-1),$C$25^(N$5-1))*IF($K11="W",1-$D$25^(N$5-1),$D$25^(N$5-1))*IF($L11="W",1-$E$25^(N$5-1),$E$25^(N$5-1))*IF($M11="W",1-$F$25^(N$5-1),$F$25^(N$5-1)) -> 0 | O11: =IF($I11="W",1-$B$25^(O$5-1),$B$25^(O$5-1))*IF($J11="W",1-$C$25^(O$5-1),$C$25^(O$5-1))*IF($K11="W",1-$D$25^(O$5-1),$D$25^(O$5-1))*IF($L11="W",1-$E$25^(O$5-1),$E$25^(O$5-1))*IF($M11="W",1-$F$25^(O$5-1),$F$25^(O$5-1)) -> 0.0048076923 | P11: =IF($I11="W",1-$B$25^(P$5-1),$B$25^(P$5-1))*IF($J11="W",1-$C$25^(P$5-1),$C$25^(P$5-1))*IF($K11="W",1-$D$25^(P$5-1),$D$25^(P$5-1))*IF($L11="W",1-$E$25^(P$5-1),$E$25^(P$5-1))*IF($M11="W",1-$F$25^(P$5-1),$F$25^(P$5-1)) -> 0.014353735 | Q11: =IF($I11="W",1-$B$25^(Q$5-1),$B$25^(Q$5-1))*IF($J11="W",1-$C$25^(Q$5-1),$C$25^(Q$5-1))*IF($K11="W",1-$D$25^(Q$5-1),$D$25^(Q$5-1))*IF($L11="W",1-$E$25^(Q$5-1),$E$25^(Q$5-1))*IF($M11="W",1-$F$25^(Q$5-1),$F$25^(Q$5-1)) -> 0.024131695 | R11: =IF($I11="W",1-$B$25^(R$5-1),$B$25^(R$5-1))*IF($J11="W",1-$C$25^(R$5-1),$C$25^(R$5-1))*IF($K11="W",1-$D$25^(R$5-1),$D$25^(R$5-1))*IF($L11="W",1-$E$25^(R$5-1),$E$25^(R$5-1))*IF($M11="W",1-$F$25^(R$5-1),$F$25^(R$5-1)) -> 0.032090538 | S11: =IF($I11="W",1-$B$25^(S$5-1),$B$25^(S$5-1))*IF($J11="W",1-$C$25^(S$5-1),$C$25^(S$5-1))*IF($K11="W",1-$D$25^(S$5-1),$D$25^(S$5-1))*IF($L11="W",1-$E$25^(S$5-1),$E$25^(S$5-1))*IF($M11="W",1-$F$25^(S$5-1),$F$25^(S$5-1)) -> 0.03754732 | T11: =IF($I11="W",1-$B$25^(T$5-1),$B$25^(T$5-1))*IF($J11="W",1-$C$25^(T$5-1),$C$25^(T$5-1))*IF($K11="W",1-$D$25^(T$5-1),$D$25^(T$5-1))*IF($L11="W",1-$E$25^(T$5-1),$E$25^(T$5-1))*IF($M11="W",1-$F$25^(T$5-1),$F$25^(T$5-1)) -> 0.040531451 | U11: =IF($I11="W",1-$B$25^(U$5-1),$B$25^(U$5-1))*IF($J11="W",1-$C$25^(U$5-1),$C$25^(U$5-1))*IF($K11="W",1-$D$25^(U$5-1),$D$25^(U$5-1))*IF($L11="W",1-$E$25^(U$5-1),$E$25^(U$5-1))*IF($M11="W",1-$F$25^(U$5-1),$F$25^(U$5-1)) -> 0.041400306 | ... W11: =IF($I11="W",1-$B$25^(W$5-1),$B$25^(W$5-1))*IF($J11="W",1-$C$25^(W$5-1),$C$25^(W$5-1))*IF($K11="W",1-$D$25^(W$5-1),$D$25^(W$5-1))*IF($L11="W",1-$E$25^(W$5-1),$E$25^(W$5-1))*IF($M11="W",1-$F$25^(W$5-1),$F$25^(W$5-1)) -> 0.038665273
A12: 7 | B12: A | C12: A | D12: A | E12: A | F12: A | H12: 6 | K12: W | L12: W | N12: =IF($I12="W",1-$B$25^(N$5-1),$B$25^(N$5-1))*IF($J12="W",1-$C$25^(N$5-1),$C$25^(N$5-1))*IF($K12="W",1-$D$25^(N$5-1),$D$25^(N$5-1))*IF($L12="W",1-$E$25^(N$5-1),$E$25^(N$5-1))*IF($M12="W",1-$F$25^(N$5-1),$F$25^(N$5-1)) -> 0 | O12: =IF($I12="W",1-$B$25^(O$5-1),$B$25^(O$5-1))*IF($J12="W",1-$C$25^(O$5-1),$C$25^(O$5-1))*IF($K12="W",1-$D$25^(O$5-1),$D$25^(O$5-1))*IF($L12="W",1-$E$25^(O$5-1),$E$25^(O$5-1))*IF($M12="W",1-$F$25^(O$5-1),$F$25^(O$5-1)) -> 0.0044070513 | P12: =IF($I12="W",1-$B$25^(P$5-1),$B$25^(P$5-1))*IF($J12="W",1-$C$25^(P$5-1),$C$25^(P$5-1))*IF($K12="W",1-$D$25^(P$5-1),$D$25^(P$5-1))*IF($L12="W",1-$E$25^(P$5-1),$E$25^(P$5-1))*IF($M12="W",1-$F$25^(P$5-1),$F$25^(P$5-1)) -> 0.013109918 | Q12: =IF($I12="W",1-$B$25^(Q$5-1),$B$25^(Q$5-1))*IF($J12="W",1-$C$25^(Q$5-1),$C$25^(Q$5-1))*IF($K12="W",1-$D$25^(Q$5-1),$D$25^(Q$5-1))*IF($L12="W",1-$E$25^(Q$5-1),$E$25^(Q$5-1))*IF($M12="W",1-$F$25^(Q$5-1),$F$25^(Q$5-1)) -> 0.021958592 | R12: =IF($I12="W",1-$B$25^(R$5-1),$B$25^(R$5-1))*IF($J12="W",1-$C$25^(R$5-1),$C$25^(R$5-1))*IF($K12="W",1-$D$25^(R$5-1),$D$25^(R$5-1))*IF($L12="W",1-$E$25^(R$5-1),$E$25^(R$5-1))*IF($M12="W",1-$F$25^(R$5-1),$F$25^(R$5-1)) -> 0.029089308 | S12: =IF($I12="W",1-$B$25^(S$5-1),$B$25^(S$5-1))*IF($J12="W",1-$C$25^(S$5-1),$C$25^(S$5-1))*IF($K12="W",1-$D$25^(S$5-1),$D$25^(S$5-1))*IF($L12="W",1-$E$25^(S$5-1),$E$25^(S$5-1))*IF($M12="W",1-$F$25^(S$5-1),$F$25^(S$5-1)) -> 0.033902632 | T12: =IF($I12="W",1-$B$25^(T$5-1),$B$25^(T$5-1))*IF($J12="W",1-$C$25^(T$5-1),$C$25^(T$5-1))*IF($K12="W",1-$D$25^(T$5-1),$D$25^(T$5-1))*IF($L12="W",1-$E$25^(T$5-1),$E$25^(T$5-1))*IF($M12="W",1-$F$25^(T$5-1),$F$25^(T$5-1)) -> 0.036450485 | U12: =IF($I12="W",1-$B$25^(U$5-1),$B$25^(U$5-1))*IF($J12="W",1-$C$25^(U$5-1),$C$25^(U$5-1))*IF($K12="W",1-$D$25^(U$5-1),$D$25^(U$5-1))*IF($L12="W",1-$E$25^(U$5-1),$E$25^(U$5-1))*IF($M12="W",1-$F$25^(U$5-1),$F$25^(U$5-1)) -> 0.037079196 | ... W12: =IF($I12="W",1-$B$25^(W$5-1),$B$25^(W$5-1))*IF($J12="W",1-$C$25^(W$5-1),$C$25^(W$5-1))*IF($K12="W",1-$D$25^(W$5-1),$D$25^(W$5-1))*IF($L12="W",1-$E$25^(W$5-1),$E$25^(W$5-1))*IF($M12="W",1-$F$25^(W$5-1),$F$25^(W$5-1)) -> 0.034336602
A13: 8 | B13: K | C13: K | D13: K | E13: K | F13: K | H13: 7 | K13: W | L13: W | M13: W | N13: =IF($I13="W",1-$B$25^(N$5-1),$B$25^(N$5-1))*IF($J13="W",1-$C$25^(N$5-1),$C$25^(N$5-1))*IF($K13="W",1-$D$25^(N$5-1),$D$25^(N$5-1))*IF($L13="W",1-$E$25^(N$5-1),$E$25^(N$5-1))*IF($M13="W",1-$F$25^(N$5-1),$F$25^(N$5-1)) -> 0 | O13: =IF($I13="W",1-$B$25^(O$5-1),$B$25^(O$5-1))*IF($J13="W",1-$C$25^(O$5-1),$C$25^(O$5-1))*IF($K13="W",1-$D$25^(O$5-1),$D$25^(O$5-1))*IF($L13="W",1-$E$25^(O$5-1),$E$25^(O$5-1))*IF($M13="W",1-$F$25^(O$5-1),$F$25^(O$5-1)) -> 0.00040064103 | P13: =IF($I13="W",1-$B$25^(P$5-1),$B$25^(P$5-1))*IF($J13="W",1-$C$25^(P$5-1),$C$25^(P$5-1))*IF($K13="W",1-$D$25^(P$5-1),$D$25^(P$5-1))*IF($L13="W",1-$E$25^(P$5-1),$E$25^(P$5-1))*IF($M13="W",1-$F$25^(P$5-1),$F$25^(P$5-1)) -> 0.0024919679 | Q13: =IF($I13="W",1-$B$25^(Q$5-1),$B$25^(Q$5-1))*IF($J13="W",1-$C$25^(Q$5-1),$C$25^(Q$5-1))*IF($K13="W",1-$D$25^(Q$5-1),$D$25^(Q$5-1))*IF($L13="W",1-$E$25^(Q$5-1),$E$25^(Q$5-1))*IF($M13="W",1-$F$25^(Q$5-1),$F$25^(Q$5-1)) -> 0.0065496325 | R13: =IF($I13="W",1-$B$25^(R$5-1),$B$25^(R$5-1))*IF($J13="W",1-$C$25^(R$5-1),$C$25^(R$5-1))*IF($K13="W",1-$D$25^(R$5-1),$D$25^(R$5-1))*IF($L13="W",1-$E$25^(R$5-1),$E$25^(R$5-1))*IF($M13="W",1-$F$25^(R$5-1),$F$25^(R$5-1)) -> 0.012109783 | S13: =IF($I13="W",1-$B$25^(S$5-1),$B$25^(S$5-1))*IF($J13="W",1-$C$25^(S$5-1),$C$25^(S$5-1))*IF($K13="W",1-$D$25^(S$5-1),$D$25^(S$5-1))*IF($L13="W",1-$E$25^(S$5-1),$E$25^(S$5-1))*IF($M13="W",1-$F$25^(S$5-1),$F$25^(S$5-1)) -> 0.018478662 | T13: =IF($I13="W",1-$B$25^(T$5-1),$B$25^(T$5-1))*IF($J13="W",1-$C$25^(T$5-1),$C$25^(T$5-1))*IF($K13="W",1-$D$25^(T$5-1),$D$25^(T$5-1))*IF($L13="W",1-$E$25^(T$5-1),$E$25^(T$5-1))*IF($M13="W",1-$F$25^(T$5-1),$F$25^(T$5-1)) -> 0.024987176 | U13: =IF($I13="W",1-$B$25^(U$5-1),$B$25^(U$5-1))*IF($J13="W",1-$C$25^(U$5-1),$C$25^(U$5-1))*IF($K13="W",1-$D$25^(U$5-1),$D$25^(U$5-1))*IF($L13="W",1-$E$25^(U$5-1),$E$25^(U$5-1))*IF($M13="W",1-$F$25^(U$5-1),$F$25^(U$5-1)) -> 0.031099742 | ... W13: =IF($I13="W",1-$B$25^(W$5-1),$B$25^(W$5-1))*IF($J13="W",1-$C$25^(W$5-1),$C$25^(W$5-1))*IF($K13="W",1-$D$25^(W$5-1),$D$25^(W$5-1))*IF($L13="W",1-$E$25^(W$5-1),$E$25^(W$5-1))*IF($M13="W",1-$F$25^(W$5-1),$F$25^(W$5-1)) -> 0.040800487
A14: 9 | B14: Q | C14: Q | D14: Q | E14: Q | F14: Q | H14: 8 | J14: W | N14: =IF($I14="W",1-$B$25^(N$5-1),$B$25^(N$5-1))*IF($J14="W",1-$C$25^(N$5-1),$C$25^(N$5-1))*IF($K14="W",1-$D$25^(N$5-1),$D$25^(N$5-1))*IF($L14="W",1-$E$25^(N$5-1),$E$25^(N$5-1))*IF($M14="W",1-$F$25^(N$5-1),$F$25^(N$5-1)) -> 0 | O14: =IF($I14="W",1-$B$25^(O$5-1),$B$25^(O$5-1))*IF($J14="W",1-$C$25^(O$5-1),$C$25^(O$5-1))*IF($K14="W",1-$D$25^(O$5-1),$D$25^(O$5-1))*IF($L14="W",1-$E$25^(O$5-1),$E$25^(O$5-1))*IF($M14="W",1-$F$25^(O$5-1),$F$25^(O$5-1)) -> 0.049107143 | P14: =IF($I14="W",1-$B$25^(P$5-1),$B$25^(P$5-1))*IF($J14="W",1-$C$25^(P$5-1),$C$25^(P$5-1))*IF($K14="W",1-$D$25^(P$5-1),$D$25^(P$5-1))*IF($L14="W",1-$E$25^(P$5-1),$E$25^(P$5-1))*IF($M14="W",1-$F$25^(P$5-1),$F$25^(P$5-1)) -> 0.069933833 | Q14: =IF($I14="W",1-$B$25^(Q$5-1),$B$25^(Q$5-1))*IF($J14="W",1-$C$25^(Q$5-1),$C$25^(Q$5-1))*IF($K14="W",1-$D$25^(Q$5-1),$D$25^(Q$5-1))*IF($L14="W",1-$E$25^(Q$5-1),$E$25^(Q$5-1))*IF($M14="W",1-$F$25^(Q$5-1),$F$25^(Q$5-1)) -> 0.074724559 | R14: =IF($I14="W",1-$B$25^(R$5-1),$B$25^(R$5-1))*IF($J14="W",1-$C$25^(R$5-1),$C$25^(R$5-1))*IF($K14="W",1-$D$25^(R$5-1),$D$25^(R$5-1))*IF($L14="W",1-$E$25^(R$5-1),$E$25^(R$5-1))*IF($M14="W",1-$F$25^(R$5-1),$F$25^(R$5-1)) -> 0.071000067 | S14: =IF($I14="W",1-$B$25^(S$5-1),$B$25^(S$5-1))*IF($J14="W",1-$C$25^(S$5-1),$C$25^(S$5-1))*IF($K14="W",1-$D$25^(S$5-1),$D$25^(S$5-1))*IF($L14="W",1-$E$25^(S$5-1),$E$25^(S$5-1))*IF($M14="W",1-$F$25^(S$5-1),$F$25^(S$5-1)) -> 0.063269886 | T14: =IF($I14="W",1-$B$25^(T$5-1),$B$25^(T$5-1))*IF($J14="W",1-$C$25^(T$5-1),$C$25^(T$5-1))*IF($K14="W",1-$D$25^(T$5-1),$D$25^(T$5-1))*IF($L14="W",1-$E$25^(T$5-1),$E$25^(T$5-1))*IF($M14="W",1-$F$25^(T$5-1),$F$25^(T$5-1)) -> 0.054147426 | U14: =IF($I14="W",1-$B$25^(U$5-1),$B$25^(U$5-1))*IF($J14="W",1-$C$25^(U$5-1),$C$25^(U$5-1))*IF($K14="W",1-$D$25^(U$5-1),$D$25^(U$5-1))*IF($L14="W",1-$E$25^(U$5-1),$E$25^(U$5-1))*IF($M14="W",1-$F$25^(U$5-1),$F$25^(U$5-1)) -> 0.045070764 | ... W14: =IF($I14="W",1-$B$25^(W$5-1),$B$25^(W$5-1))*IF($J14="W",1-$C$25^(W$5-1),$C$25^(W$5-1))*IF($K14="W",1-$D$25^(W$5-1),$D$25^(W$5-1))*IF($L14="W",1-$E$25^(W$5-1),$E$25^(W$5-1))*IF($M14="W",1-$F$25^(W$5-1),$F$25^(W$5-1)) -> 0.029531822
A15: 10 | B15: J | C15: J | D15: J | E15: J | F15: J | H15: 9 | J15: W | M15: W | N15: =IF($I15="W",1-$B$25^(N$5-1),$B$25^(N$5-1))*IF($J15="W",1-$C$25^(N$5-1),$C$25^(N$5-1))*IF($K15="W",1-$D$25^(N$5-1),$D$25^(N$5-1))*IF($L15="W",1-$E$25^(N$5-1),$E$25^(N$5-1))*IF($M15="W",1-$F$25^(N$5-1),$F$25^(N$5-1)) -> 0 | O15: =IF($I15="W",1-$B$25^(O$5-1),$B$25^(O$5-1))*IF($J15="W",1-$C$25^(O$5-1),$C$25^(O$5-1))*IF($K15="W",1-$D$25^(O$5-1),$D$25^(O$5-1))*IF($L15="W",1-$E$25^(O$5-1),$E$25^(O$5-1))*IF($M15="W",1-$F$25^(O$5-1),$F$25^(O$5-1)) -> 0.0044642857 | P15: =IF($I15="W",1-$B$25^(P$5-1),$B$25^(P$5-1))*IF($J15="W",1-$C$25^(P$5-1),$C$25^(P$5-1))*IF($K15="W",1-$D$25^(P$5-1),$D$25^(P$5-1))*IF($L15="W",1-$E$25^(P$5-1),$E$25^(P$5-1))*IF($M15="W",1-$F$25^(P$5-1),$F$25^(P$5-1)) -> 0.013293208 | Q15: =IF($I15="W",1-$B$25^(Q$5-1),$B$25^(Q$5-1))*IF($J15="W",1-$C$25^(Q$5-1),$C$25^(Q$5-1))*IF($K15="W",1-$D$25^(Q$5-1),$D$25^(Q$5-1))*IF($L15="W",1-$E$25^(Q$5-1),$E$25^(Q$5-1))*IF($M15="W",1-$F$25^(Q$5-1),$F$25^(Q$5-1)) -> 0.022288242 | R15: =IF($I15="W",1-$B$25^(R$5-1),$B$25^(R$5-1))*IF($J15="W",1-$C$25^(R$5-1),$C$25^(R$5-1))*IF($K15="W",1-$D$25^(R$5-1),$D$25^(R$5-1))*IF($L15="W",1-$E$25^(R$5-1),$E$25^(R$5-1))*IF($M15="W",1-$F$25^(R$5-1),$F$25^(R$5-1)) -> 0.029557094 | S15: =IF($I15="W",1-$B$25^(S$5-1),$B$25^(S$5-1))*IF($J15="W",1-$C$25^(S$5-1),$C$25^(S$5-1))*IF($K15="W",1-$D$25^(S$5-1),$D$25^(S$5-1))*IF($L15="W",1-$E$25^(S$5-1),$E$25^(S$5-1))*IF($M15="W",1-$F$25^(S$5-1),$F$25^(S$5-1)) -> 0.034485311 | T15: =IF($I15="W",1-$B$25^(T$5-1),$B$25^(T$5-1))*IF($J15="W",1-$C$25^(T$5-1),$C$25^(T$5-1))*IF($K15="W",1-$D$25^(T$5-1),$D$25^(T$5-1))*IF($L15="W",1-$E$25^(T$5-1),$E$25^(T$5-1))*IF($M15="W",1-$F$25^(T$5-1),$F$25^(T$5-1)) -> 0.037118608 | U15: =IF($I15="W",1-$B$25^(U$5-1),$B$25^(U$5-1))*IF($J15="W",1-$C$25^(U$5-1),$C$25^(U$5-1))*IF($K15="W",1-$D$25^(U$5-1),$D$25^(U$5-1))*IF($L15="W",1-$E$25^(U$5-1),$E$25^(U$5-1))*IF($M15="W",1-$F$25^(U$5-1),$F$25^(U$5-1)) -> 0.037802577 | ... W15: =IF($I15="W",1-$B$25^(W$5-1),$B$25^(W$5-1))*IF($J15="W",1-$C$25^(W$5-1),$C$25^(W$5-1))*IF($K15="W",1-$D$25^(W$5-1),$D$25^(W$5-1))*IF($L15="W",1-$E$25^(W$5-1),$E$25^(W$5-1))*IF($M15="W",1-$F$25^(W$5-1),$F$25^(W$5-1)) -> 0.035091204
A16: 11 | B16: 10 | C16: 10 | D16: 10 | E16: 10 | F16: 10 | H16: 10 | J16: W | L16: W | N16: =IF($I16="W",1-$B$25^(N$5-1),$B$25^(N$5-1))*IF($J16="W",1-$C$25^(N$5-1),$C$25^(N$5-1))*IF($K16="W",1-$D$25^(N$5-1),$D$25^(N$5-1))*IF($L16="W",1-$E$25^(N$5-1),$E$25^(N$5-1))*IF($M16="W",1-$F$25^(N$5-1),$F$25^(N$5-1)) -> 0 | O16: =IF($I16="W",1-$B$25^(O$5-1),$B$25^(O$5-1))*IF($J16="W",1-$C$25^(O$5-1),$C$25^(O$5-1))*IF($K16="W",1-$D$25^(O$5-1),$D$25^(O$5-1))*IF($L16="W",1-$E$25^(O$5-1),$E$25^(O$5-1))*IF($M16="W",1-$F$25^(O$5-1),$F$25^(O$5-1)) -> 0.0040922619 | P16: =IF($I16="W",1-$B$25^(P$5-1),$B$25^(P$5-1))*IF($J16="W",1-$C$25^(P$5-1),$C$25^(P$5-1))*IF($K16="W",1-$D$25^(P$5-1),$D$25^(P$5-1))*IF($L16="W",1-$E$25^(P$5-1),$E$25^(P$5-1))*IF($M16="W",1-$F$25^(P$5-1),$F$25^(P$5-1)) -> 0.01214129 | Q16: =IF($I16="W",1-$B$25^(Q$5-1),$B$25^(Q$5-1))*IF($J16="W",1-$C$25^(Q$5-1),$C$25^(Q$5-1))*IF($K16="W",1-$D$25^(Q$5-1),$D$25^(Q$5-1))*IF($L16="W",1-$E$25^(Q$5-1),$E$25^(Q$5-1))*IF($M16="W",1-$F$25^(Q$5-1),$F$25^(Q$5-1)) -> 0.020281145 | R16: =IF($I16="W",1-$B$25^(R$5-1),$B$25^(R$5-1))*IF($J16="W",1-$C$25^(R$5-1),$C$25^(R$5-1))*IF($K16="W",1-$D$25^(R$5-1),$D$25^(R$5-1))*IF($L16="W",1-$E$25^(R$5-1),$E$25^(R$5-1))*IF($M16="W",1-$F$25^(R$5-1),$F$25^(R$5-1)) -> 0.026792801 | S16: =IF($I16="W",1-$B$25^(S$5-1),$B$25^(S$5-1))*IF($J16="W",1-$C$25^(S$5-1),$C$25^(S$5-1))*IF($K16="W",1-$D$25^(S$5-1),$D$25^(S$5-1))*IF($L16="W",1-$E$25^(S$5-1),$E$25^(S$5-1))*IF($M16="W",1-$F$25^(S$5-1),$F$25^(S$5-1)) -> 0.03113785 | T16: =IF($I16="W",1-$B$25^(T$5-1),$B$25^(T$5-1))*IF($J16="W",1-$C$25^(T$5-1),$C$25^(T$5-1))*IF($K16="W",1-$D$25^(T$5-1),$D$25^(T$5-1))*IF($L16="W",1-$E$25^(T$5-1),$E$25^(T$5-1))*IF($M16="W",1-$F$25^(T$5-1),$F$25^(T$5-1)) -> 0.033381269 | U16: =IF($I16="W",1-$B$25^(U$5-1),$B$25^(U$5-1))*IF($J16="W",1-$C$25^(U$5-1),$C$25^(U$5-1))*IF($K16="W",1-$D$25^(U$5-1),$D$25^(U$5-1))*IF($L16="W",1-$E$25^(U$5-1),$E$25^(U$5-1))*IF($M16="W",1-$F$25^(U$5-1),$F$25^(U$5-1)) -> 0.033856975 | ... W16: =IF($I16="W",1-$B$25^(W$5-1),$B$25^(W$5-1))*IF($J16="W",1-$C$25^(W$5-1),$C$25^(W$5-1))*IF($K16="W",1-$D$25^(W$5-1),$D$25^(W$5-1))*IF($L16="W",1-$E$25^(W$5-1),$E$25^(W$5-1))*IF($M16="W",1-$F$25^(W$5-1),$F$25^(W$5-1)) -> 0.031162658
A17: 12 | B17: A | C17: A | D17: A | E17: A | F17: A | H17: 11 | J17: W | L17: W | M17: W | N17: =IF($I17="W",1-$B$25^(N$5-1),$B$25^(N$5-1))*IF($J17="W",1-$C$25^(N$5-1),$C$25^(N$5-1))*IF($K17="W",1-$D$25^(N$5-1),$D$25^(N$5-1))*IF($L17="W",1-$E$25^(N$5-1),$E$25^(N$5-1))*IF($M17="W",1-$F$25^(N$5-1),$F$25^(N$5-1)) -> 0 | O17: =IF($I17="W",1-$B$25^(O$5-1),$B$25^(O$5-1))*IF($J17="W",1-$C$25^(O$5-1),$C$25^(O$5-1))*IF($K17="W",1-$D$25^(O$5-1),$D$25^(O$5-1))*IF($L17="W",1-$E$25^(O$5-1),$E$25^(O$5-1))*IF($M17="W",1-$F$25^(O$5-1),$F$25^(O$5-1)) -> 0.00037202381 | P17: =IF($I17="W",1-$B$25^(P$5-1),$B$25^(P$5-1))*IF($J17="W",1-$C$25^(P$5-1),$C$25^(P$5-1))*IF($K17="W",1-$D$25^(P$5-1),$D$25^(P$5-1))*IF($L17="W",1-$E$25^(P$5-1),$E$25^(P$5-1))*IF($M17="W",1-$F$25^(P$5-1),$F$25^(P$5-1)) -> 0.0023078486 | Q17: =IF($I17="W",1-$B$25^(Q$5-1),$B$25^(Q$5-1))*IF($J17="W",1-$C$25^(Q$5-1),$C$25^(Q$5-1))*IF($K17="W",1-$D$25^(Q$5-1),$D$25^(Q$5-1))*IF($L17="W",1-$E$25^(Q$5-1),$E$25^(Q$5-1))*IF($M17="W",1-$F$25^(Q$5-1),$F$25^(Q$5-1)) -> 0.0060492971 | R17: =IF($I17="W",1-$B$25^(R$5-1),$B$25^(R$5-1))*IF($J17="W",1-$C$25^(R$5-1),$C$25^(R$5-1))*IF($K17="W",1-$D$25^(R$5-1),$D$25^(R$5-1))*IF($L17="W",1-$E$25^(R$5-1),$E$25^(R$5-1))*IF($M17="W",1-$F$25^(R$5-1),$F$25^(R$5-1)) -> 0.011153755 | S17: =IF($I17="W",1-$B$25^(S$5-1),$B$25^(S$5-1))*IF($J17="W",1-$C$25^(S$5-1),$C$25^(S$5-1))*IF($K17="W",1-$D$25^(S$5-1),$D$25^(S$5-1))*IF($L17="W",1-$E$25^(S$5-1),$E$25^(S$5-1))*IF($M17="W",1-$F$25^(S$5-1),$F$25^(S$5-1)) -> 0.016971715 | T17: =IF($I17="W",1-$B$25^(T$5-1),$B$25^(T$5-1))*IF($J17="W",1-$C$25^(T$5-1),$C$25^(T$5-1))*IF($K17="W",1-$D$25^(T$5-1),$D$25^(T$5-1))*IF($L17="W",1-$E$25^(T$5-1),$E$25^(T$5-1))*IF($M17="W",1-$F$25^(T$5-1),$F$25^(T$5-1)) -> 0.022883198 | U17: =IF($I17="W",1-$B$25^(U$5-1),$B$25^(U$5-1))*IF($J17="W",1-$C$25^(U$5-1),$C$25^(U$5-1))*IF($K17="W",1-$D$25^(U$5-1),$D$25^(U$5-1))*IF($L17="W",1-$E$25^(U$5-1),$E$25^(U$5-1))*IF($M17="W",1-$F$25^(U$5-1),$F$25^(U$5-1)) -> 0.028397142 | ... W17: =IF($I17="W",1-$B$25^(W$5-1),$B$25^(W$5-1))*IF($J17="W",1-$C$25^(W$5-1),$C$25^(W$5-1))*IF($K17="W",1-$D$25^(W$5-1),$D$25^(W$5-1))*IF($L17="W",1-$E$25^(W$5-1),$E$25^(W$5-1))*IF($M17="W",1-$F$25^(W$5-1),$F$25^(W$5-1)) -> 0.037029046
A18: 13 | B18: K | C18: K | D18: K | E18: K | H18: 12 | J18: W | K18: W | N18: =IF($I18="W",1-$B$25^(N$5-1),$B$25^(N$5-1))*IF($J18="W",1-$C$25^(N$5-1),$C$25^(N$5-1))*IF($K18="W",1-$D$25^(N$5-1),$D$25^(N$5-1))*IF($L18="W",1-$E$25^(N$5-1),$E$25^(N$5-1))*IF($M18="W",1-$F$25^(N$5-1),$F$25^(N$5-1)) -> 0 | O18: =IF($I18="W",1-$B$25^(O$5-1),$B$25^(O$5-1))*IF($J18="W",1-$C$25^(O$5-1),$C$25^(O$5-1))*IF($K18="W",1-$D$25^(O$5-1),$D$25^(O$5-1))*IF($L18="W",1-$E$25^(O$5-1),$E$25^(O$5-1))*IF($M18="W",1-$F$25^(O$5-1),$F$25^(O$5-1)) -> 0.0037774725 | P18: =IF($I18="W",1-$B$25^(P$5-1),$B$25^(P$5-1))*IF($J18="W",1-$C$25^(P$5-1),$C$25^(P$5-1))*IF($K18="W",1-$D$25^(P$5-1),$D$25^(P$5-1))*IF($L18="W",1-$E$25^(P$5-1),$E$25^(P$5-1))*IF($M18="W",1-$F$25^(P$5-1),$F$25^(P$5-1)) -> 0.011172861 | Q18: =IF($I18="W",1-$B$25^(Q$5-1),$B$25^(Q$5-1))*IF($J18="W",1-$C$25^(Q$5-1),$C$25^(Q$5-1))*IF($K18="W",1-$D$25^(Q$5-1),$D$25^(Q$5-1))*IF($L18="W",1-$E$25^(Q$5-1),$E$25^(Q$5-1))*IF($M18="W",1-$F$25^(Q$5-1),$F$25^(Q$5-1)) -> 0.018604613 | R18: =IF($I18="W",1-$B$25^(R$5-1),$B$25^(R$5-1))*IF($J18="W",1-$C$25^(R$5-1),$C$25^(R$5-1))*IF($K18="W",1-$D$25^(R$5-1),$D$25^(R$5-1))*IF($L18="W",1-$E$25^(R$5-1),$E$25^(R$5-1))*IF($M18="W",1-$F$25^(R$5-1),$F$25^(R$5-1)) -> 0.02449864 | S18: =IF($I18="W",1-$B$25^(S$5-1),$B$25^(S$5-1))*IF($J18="W",1-$C$25^(S$5-1),$C$25^(S$5-1))*IF($K18="W",1-$D$25^(S$5-1),$D$25^(S$5-1))*IF($L18="W",1-$E$25^(S$5-1),$E$25^(S$5-1))*IF($M18="W",1-$F$25^(S$5-1),$F$25^(S$5-1)) -> 0.028377581 | T18: =IF($I18="W",1-$B$25^(T$5-1),$B$25^(T$5-1))*IF($J18="W",1-$C$25^(T$5-1),$C$25^(T$5-1))*IF($K18="W",1-$D$25^(T$5-1),$D$25^(T$5-1))*IF($L18="W",1-$E$25^(T$5-1),$E$25^(T$5-1))*IF($M18="W",1-$F$25^(T$5-1),$F$25^(T$5-1)) -> 0.03031935 | U18: =IF($I18="W",1-$B$25^(U$5-1),$B$25^(U$5-1))*IF($J18="W",1-$C$25^(U$5-1),$C$25^(U$5-1))*IF($K18="W",1-$D$25^(U$5-1),$D$25^(U$5-1))*IF($L18="W",1-$E$25^(U$5-1),$E$25^(U$5-1))*IF($M18="W",1-$F$25^(U$5-1),$F$25^(U$5-1)) -> 0.030645243 | ... W18: =IF($I18="W",1-$B$25^(W$5-1),$B$25^(W$5-1))*IF($J18="W",1-$C$25^(W$5-1),$C$25^(W$5-1))*IF($K18="W",1-$D$25^(W$5-1),$D$25^(W$5-1))*IF($L18="W",1-$E$25^(W$5-1),$E$25^(W$5-1))*IF($M18="W",1-$F$25^(W$5-1),$F$25^(W$5-1)) -> 0.028005864
A19: 14 | B19: Q | C19: Q | D19: Q | H19: 13 | J19: W | K19: W | M19: W | N19: =IF($I19="W",1-$B$25^(N$5-1),$B$25^(N$5-1))*IF($J19="W",1-$C$25^(N$5-1),$C$25^(N$5-1))*IF($K19="W",1-$D$25^(N$5-1),$D$25^(N$5-1))*IF($L19="W",1-$E$25^(N$5-1),$E$25^(N$5-1))*IF($M19="W",1-$F$25^(N$5-1),$F$25^(N$5-1)) -> 0 | O19: =IF($I19="W",1-$B$25^(O$5-1),$B$25^(O$5-1))*IF($J19="W",1-$C$25^(O$5-1),$C$25^(O$5-1))*IF($K19="W",1-$D$25^(O$5-1),$D$25^(O$5-1))*IF($L19="W",1-$E$25^(O$5-1),$E$25^(O$5-1))*IF($M19="W",1-$F$25^(O$5-1),$F$25^(O$5-1)) -> 0.00034340659 | P19: =IF($I19="W",1-$B$25^(P$5-1),$B$25^(P$5-1))*IF($J19="W",1-$C$25^(P$5-1),$C$25^(P$5-1))*IF($K19="W",1-$D$25^(P$5-1),$D$25^(P$5-1))*IF($L19="W",1-$E$25^(P$5-1),$E$25^(P$5-1))*IF($M19="W",1-$F$25^(P$5-1),$F$25^(P$5-1)) -> 0.0021237669 | Q19: =IF($I19="W",1-$B$25^(Q$5-1),$B$25^(Q$5-1))*IF($J19="W",1-$C$25^(Q$5-1),$C$25^(Q$5-1))*IF($K19="W",1-$D$25^(Q$5-1),$D$25^(Q$5-1))*IF($L19="W",1-$E$25^(Q$5-1),$E$25^(Q$5-1))*IF($M19="W",1-$F$25^(Q$5-1),$F$25^(Q$5-1)) -> 0.0055492345 | R19: =IF($I19="W",1-$B$25^(R$5-1),$B$25^(R$5-1))*IF($J19="W",1-$C$25^(R$5-1),$C$25^(R$5-1))*IF($K19="W",1-$D$25^(R$5-1),$D$25^(R$5-1))*IF($L19="W",1-$E$25^(R$5-1),$E$25^(R$5-1))*IF($M19="W",1-$F$25^(R$5-1),$F$25^(R$5-1)) -> 0.010198703 | S19: =IF($I19="W",1-$B$25^(S$5-1),$B$25^(S$5-1))*IF($J19="W",1-$C$25^(S$5-1),$C$25^(S$5-1))*IF($K19="W",1-$D$25^(S$5-1),$D$25^(S$5-1))*IF($L19="W",1-$E$25^(S$5-1),$E$25^(S$5-1))*IF($M19="W",1-$F$25^(S$5-1),$F$25^(S$5-1)) -> 0.015467228 | T19: =IF($I19="W",1-$B$25^(T$5-1),$B$25^(T$5-1))*IF($J19="W",1-$C$25^(T$5-1),$C$25^(T$5-1))*IF($K19="W",1-$D$25^(T$5-1),$D$25^(T$5-1))*IF($L19="W",1-$E$25^(T$5-1),$E$25^(T$5-1))*IF($M19="W",1-$F$25^(T$5-1),$F$25^(T$5-1)) -> 0.020784221 | U19: =IF($I19="W",1-$B$25^(U$5-1),$B$25^(U$5-1))*IF($J19="W",1-$C$25^(U$5-1),$C$25^(U$5-1))*IF($K19="W",1-$D$25^(U$5-1),$D$25^(U$5-1))*IF($L19="W",1-$E$25^(U$5-1),$E$25^(U$5-1))*IF($M19="W",1-$F$25^(U$5-1),$F$25^(U$5-1)) -> 0.02570334 | ... W19: =IF($I19="W",1-$B$25^(W$5-1),$B$25^(W$5-1))*IF($J19="W",1-$C$25^(W$5-1),$C$25^(W$5-1))*IF($K19="W",1-$D$25^(W$5-1),$D$25^(W$5-1))*IF($L19="W",1-$E$25^(W$5-1),$E$25^(W$5-1))*IF($M19="W",1-$F$25^(W$5-1),$F$25^(W$5-1)) -> 0.033277984
A20: 15 | B20: J | C20: J | H20: 14 | J20: W | K20: W | L20: W | N20: =IF($I20="W",1-$B$25^(N$5-1),$B$25^(N$5-1))*IF($J20="W",1-$C$25^(N$5-1),$C$25^(N$5-1))*IF($K20="W",1-$D$25^(N$5-1),$D$25^(N$5-1))*IF($L20="W",1-$E$25^(N$5-1),$E$25^(N$5-1))*IF($M20="W",1-$F$25^(N$5-1),$F$25^(N$5-1)) -> 0 | O20: =IF($I20="W",1-$B$25^(O$5-1),$B$25^(O$5-1))*IF($J20="W",1-$C$25^(O$5-1),$C$25^(O$5-1))*IF($K20="W",1-$D$25^(O$5-1),$D$25^(O$5-1))*IF($L20="W",1-$E$25^(O$5-1),$E$25^(O$5-1))*IF($M20="W",1-$F$25^(O$5-1),$F$25^(O$5-1)) -> 0.00031478938 | P20: =IF($I20="W",1-$B$25^(P$5-1),$B$25^(P$5-1))*IF($J20="W",1-$C$25^(P$5-1),$C$25^(P$5-1))*IF($K20="W",1-$D$25^(P$5-1),$D$25^(P$5-1))*IF($L20="W",1-$E$25^(P$5-1),$E$25^(P$5-1))*IF($M20="W",1-$F$25^(P$5-1),$F$25^(P$5-1)) -> 0.0019397328 | Q20: =IF($I20="W",1-$B$25^(Q$5-1),$B$25^(Q$5-1))*IF($J20="W",1-$C$25^(Q$5-1),$C$25^(Q$5-1))*IF($K20="W",1-$D$25^(Q$5-1),$D$25^(Q$5-1))*IF($L20="W",1-$E$25^(Q$5-1),$E$25^(Q$5-1))*IF($M20="W",1-$F$25^(Q$5-1),$F$25^(Q$5-1)) -> 0.0050495158 | R20: =IF($I20="W",1-$B$25^(R$5-1),$B$25^(R$5-1))*IF($J20="W",1-$C$25^(R$5-1),$C$25^(R$5-1))*IF($K20="W",1-$D$25^(R$5-1),$D$25^(R$5-1))*IF($L20="W",1-$E$25^(R$5-1),$E$25^(R$5-1))*IF($M20="W",1-$F$25^(R$5-1),$F$25^(R$5-1)) -> 0.0092448814 | S20: =IF($I20="W",1-$B$25^(S$5-1),$B$25^(S$5-1))*IF($J20="W",1-$C$25^(S$5-1),$C$25^(S$5-1))*IF($K20="W",1-$D$25^(S$5-1),$D$25^(S$5-1))*IF($L20="W",1-$E$25^(S$5-1),$E$25^(S$5-1))*IF($M20="W",1-$F$25^(S$5-1),$F$25^(S$5-1)) -> 0.013965836 | T20: =IF($I20="W",1-$B$25^(T$5-1),$B$25^(T$5-1))*IF($J20="W",1-$C$25^(T$5-1),$C$25^(T$5-1))*IF($K20="W",1-$D$25^(T$5-1),$D$25^(T$5-1))*IF($L20="W",1-$E$25^(T$5-1),$E$25^(T$5-1))*IF($M20="W",1-$F$25^(T$5-1),$F$25^(T$5-1)) -> 0.018691532 | U20: =IF($I20="W",1-$B$25^(U$5-1),$B$25^(U$5-1))*IF($J20="W",1-$C$25^(U$5-1),$C$25^(U$5-1))*IF($K20="W",1-$D$25^(U$5-1),$D$25^(U$5-1))*IF($L20="W",1-$E$25^(U$5-1),$E$25^(U$5-1))*IF($M20="W",1-$F$25^(U$5-1),$F$25^(U$5-1)) -> 0.023020582 | ... W20: =IF($I20="W",1-$B$25^(W$5-1),$B$25^(W$5-1))*IF($J20="W",1-$C$25^(W$5-1),$C$25^(W$5-1))*IF($K20="W",1-$D$25^(W$5-1),$D$25^(W$5-1))*IF($L20="W",1-$E$25^(W$5-1),$E$25^(W$5-1))*IF($M20="W",1-$F$25^(W$5-1),$F$25^(W$5-1)) -> 0.029552433
A21: 16 | B21: 10 | H21: 15 | J21: W | K21: W | L21: W | M21: W | N21: =IF($I21="W",1-$B$25^(N$5-1),$B$25^(N$5-1))*IF($J21="W",1-$C$25^(N$5-1),$C$25^(N$5-1))*IF($K21="W",1-$D$25^(N$5-1),$D$25^(N$5-1))*IF($L21="W",1-$E$25^(N$5-1),$E$25^(N$5-1))*IF($M21="W",1-$F$25^(N$5-1),$F$25^(N$5-1)) -> 0 | O21: =IF($I21="W",1-$B$25^(O$5-1),$B$25^(O$5-1))*IF($J21="W",1-$C$25^(O$5-1),$C$25^(O$5-1))*IF($K21="W",1-$D$25^(O$5-1),$D$25^(O$5-1))*IF($L21="W",1-$E$25^(O$5-1),$E$25^(O$5-1))*IF($M21="W",1-$F$25^(O$5-1),$F$25^(O$5-1)) -> 2.8617216e-05 | P21: =IF($I21="W",1-$B$25^(P$5-1),$B$25^(P$5-1))*IF($J21="W",1-$C$25^(P$5-1),$C$25^(P$5-1))*IF($K21="W",1-$D$25^(P$5-1),$D$25^(P$5-1))*IF($L21="W",1-$E$25^(P$5-1),$E$25^(P$5-1))*IF($M21="W",1-$F$25^(P$5-1),$F$25^(P$5-1)) -> 0.00036870954 | Q21: =IF($I21="W",1-$B$25^(Q$5-1),$B$25^(Q$5-1))*IF($J21="W",1-$C$25^(Q$5-1),$C$25^(Q$5-1))*IF($K21="W",1-$D$25^(Q$5-1),$D$25^(Q$5-1))*IF($L21="W",1-$E$25^(Q$5-1),$E$25^(Q$5-1))*IF($M21="W",1-$F$25^(Q$5-1),$F$25^(Q$5-1)) -> 0.001506129 | R21: =IF($I21="W",1-$B$25^(R$5-1),$B$25^(R$5-1))*IF($J21="W",1-$C$25^(R$5-1),$C$25^(R$5-1))*IF($K21="W",1-$D$25^(R$5-1),$D$25^(R$5-1))*IF($L21="W",1-$E$25^(R$5-1),$E$25^(R$5-1))*IF($M21="W",1-$F$25^(R$5-1),$F$25^(R$5-1)) -> 0.0038486136 | S21: =IF($I21="W",1-$B$25^(S$5-1),$B$25^(S$5-1))*IF($J21="W",1-$C$25^(S$5-1),$C$25^(S$5-1))*IF($K21="W",1-$D$25^(S$5-1),$D$25^(S$5-1))*IF($L21="W",1-$E$25^(S$5-1),$E$25^(S$5-1))*IF($M21="W",1-$F$25^(S$5-1),$F$25^(S$5-1)) -> 0.0076120923 | T21: =IF($I21="W",1-$B$25^(T$5-1),$B$25^(T$5-1))*IF($J21="W",1-$C$25^(T$5-1),$C$25^(T$5-1))*IF($K21="W",1-$D$25^(T$5-1),$D$25^(T$5-1))*IF($L21="W",1-$E$25^(T$5-1),$E$25^(T$5-1))*IF($M21="W",1-$F$25^(T$5-1),$F$25^(T$5-1)) -> 0.012813235 | U21: =IF($I21="W",1-$B$25^(U$5-1),$B$25^(U$5-1))*IF($J21="W",1-$C$25^(U$5-1),$C$25^(U$5-1))*IF($K21="W",1-$D$25^(U$5-1),$D$25^(U$5-1))*IF($L21="W",1-$E$25^(U$5-1),$E$25^(U$5-1))*IF($M21="W",1-$F$25^(U$5-1),$F$25^(U$5-1)) -> 0.019308245 | ... W21: =IF($I21="W",1-$B$25^(W$5-1),$B$25^(W$5-1))*IF($J21="W",1-$C$25^(W$5-1),$C$25^(W$5-1))*IF($K21="W",1-$D$25^(W$5-1),$D$25^(W$5-1))*IF($L21="W",1-$E$25^(W$5-1),$E$25^(W$5-1))*IF($M21="W",1-$F$25^(W$5-1),$F$25^(W$5-1)) -> 0.035115694
H22: 16 | I22: W | N22: =IF($I22="W",1-$B$25^(N$5-1),$B$25^(N$5-1))*IF($J22="W",1-$C$25^(N$5-1),$C$25^(N$5-1))*IF($K22="W",1-$D$25^(N$5-1),$D$25^(N$5-1))*IF($L22="W",1-$E$25^(N$5-1),$E$25^(N$5-1))*IF($M22="W",1-$F$25^(N$5-1),$F$25^(N$5-1)) -> 0 | O22: =IF($I22="W",1-$B$25^(O$5-1),$B$25^(O$5-1))*IF($J22="W",1-$C$25^(O$5-1),$C$25^(O$5-1))*IF($K22="W",1-$D$25^(O$5-1),$D$25^(O$5-1))*IF($L22="W",1-$E$25^(O$5-1),$E$25^(O$5-1))*IF($M22="W",1-$F$25^(O$5-1),$F$25^(O$5-1)) -> 0.045833333 | P22: =IF($I22="W",1-$B$25^(P$5-1),$B$25^(P$5-1))*IF($J22="W",1-$C$25^(P$5-1),$C$25^(P$5-1))*IF($K22="W",1-$D$25^(P$5-1),$D$25^(P$5-1))*IF($L22="W",1-$E$25^(P$5-1),$E$25^(P$5-1))*IF($M22="W",1-$F$25^(P$5-1),$F$25^(P$5-1)) -> 0.065121528 | Q22: =IF($I22="W",1-$B$25^(Q$5-1),$B$25^(Q$5-1))*IF($J22="W",1-$C$25^(Q$5-1),$C$25^(Q$5-1))*IF($K22="W",1-$D$25^(Q$5-1),$D$25^(Q$5-1))*IF($L22="W",1-$E$25^(Q$5-1),$E$25^(Q$5-1))*IF($M22="W",1-$F$25^(Q$5-1),$F$25^(Q$5-1)) -> 0.069419198 | R22: =IF($I22="W",1-$B$25^(R$5-1),$B$25^(R$5-1))*IF($J22="W",1-$C$25^(R$5-1),$C$25^(R$5-1))*IF($K22="W",1-$D$25^(R$5-1),$D$25^(R$5-1))*IF($L22="W",1-$E$25^(R$5-1),$E$25^(R$5-1))*IF($M22="W",1-$F$25^(R$5-1),$F$25^(R$5-1)) -> 0.065801008 | S22: =IF($I22="W",1-$B$25^(S$5-1),$B$25^(S$5-1))*IF($J22="W",1-$C$25^(S$5-1),$C$25^(S$5-1))*IF($K22="W",1-$D$25^(S$5-1),$D$25^(S$5-1))*IF($L22="W",1-$E$25^(S$5-1),$E$25^(S$5-1))*IF($M22="W",1-$F$25^(S$5-1),$F$25^(S$5-1)) -> 0.058493419 | T22: =IF($I22="W",1-$B$25^(T$5-1),$B$25^(T$5-1))*IF($J22="W",1-$C$25^(T$5-1),$C$25^(T$5-1))*IF($K22="W",1-$D$25^(T$5-1),$D$25^(T$5-1))*IF($L22="W",1-$E$25^(T$5-1),$E$25^(T$5-1))*IF($M22="W",1-$F$25^(T$5-1),$F$25^(T$5-1)) -> 0.049934725 | U22: =IF($I22="W",1-$B$25^(U$5-1),$B$25^(U$5-1))*IF($J22="W",1-$C$25^(U$5-1),$C$25^(U$5-1))*IF($K22="W",1-$D$25^(U$5-1),$D$25^(U$5-1))*IF($L22="W",1-$E$25^(U$5-1),$E$25^(U$5-1))*IF($M22="W",1-$F$25^(U$5-1),$F$25^(U$5-1)) -> 0.04145849 | ... W22: =IF($I22="W",1-$B$25^(W$5-1),$B$25^(W$5-1))*IF($J22="W",1-$C$25^(W$5-1),$C$25^(W$5-1))*IF($K22="W",1-$D$25^(W$5-1),$D$25^(W$5-1))*IF($L22="W",1-$E$25^(W$5-1),$E$25^(W$5-1))*IF($M22="W",1-$F$25^(W$5-1),$F$25^(W$5-1)) -> 0.027022976
A23: WILD | B23: R1 | C23: R2 | D23: R3 | E23: R4 | F23: R5 | H23: 17 | I23: W | M23: W | N23: =IF($I23="W",1-$B$25^(N$5-1),$B$25^(N$5-1))*IF($J23="W",1-$C$25^(N$5-1),$C$25^(N$5-1))*IF($K23="W",1-$D$25^(N$5-1),$D$25^(N$5-1))*IF($L23="W",1-$E$25^(N$5-1),$E$25^(N$5-1))*IF($M23="W",1-$F$25^(N$5-1),$F$25^(N$5-1)) -> 0 | O23: =IF($I23="W",1-$B$25^(O$5-1),$B$25^(O$5-1))*IF($J23="W",1-$C$25^(O$5-1),$C$25^(O$5-1))*IF($K23="W",1-$D$25^(O$5-1),$D$25^(O$5-1))*IF($L23="W",1-$E$25^(O$5-1),$E$25^(O$5-1))*IF($M23="W",1-$F$25^(O$5-1),$F$25^(O$5-1)) -> 0.0041666667 | P23: =IF($I23="W",1-$B$25^(P$5-1),$B$25^(P$5-1))*IF($J23="W",1-$C$25^(P$5-1),$C$25^(P$5-1))*IF($K23="W",1-$D$25^(P$5-1),$D$25^(P$5-1))*IF($L23="W",1-$E$25^(P$5-1),$E$25^(P$5-1))*IF($M23="W",1-$F$25^(P$5-1),$F$25^(P$5-1)) -> 0.012378472 | Q23: =IF($I23="W",1-$B$25^(Q$5-1),$B$25^(Q$5-1))*IF($J23="W",1-$C$25^(Q$5-1),$C$25^(Q$5-1))*IF($K23="W",1-$D$25^(Q$5-1),$D$25^(Q$5-1))*IF($L23="W",1-$E$25^(Q$5-1),$E$25^(Q$5-1))*IF($M23="W",1-$F$25^(Q$5-1),$F$25^(Q$5-1)) -> 0.020705802 | R23: =IF($I23="W",1-$B$25^(R$5-1),$B$25^(R$5-1))*IF($J23="W",1-$C$25^(R$5-1),$C$25^(R$5-1))*IF($K23="W",1-$D$25^(R$5-1),$D$25^(R$5-1))*IF($L23="W",1-$E$25^(R$5-1),$E$25^(R$5-1))*IF($M23="W",1-$F$25^(R$5-1),$F$25^(R$5-1)) -> 0.027392742 | S23: =IF($I23="W",1-$B$25^(S$5-1),$B$25^(S$5-1))*IF($J23="W",1-$C$25^(S$5-1),$C$25^(S$5-1))*IF($K23="W",1-$D$25^(S$5-1),$D$25^(S$5-1))*IF($L23="W",1-$E$25^(S$5-1),$E$25^(S$5-1))*IF($M23="W",1-$F$25^(S$5-1),$F$25^(S$5-1)) -> 0.031881893 | T23: =IF($I23="W",1-$B$25^(T$5-1),$B$25^(T$5-1))*IF($J23="W",1-$C$25^(T$5-1),$C$25^(T$5-1))*IF($K23="W",1-$D$25^(T$5-1),$D$25^(T$5-1))*IF($L23="W",1-$E$25^(T$5-1),$E$25^(T$5-1))*IF($M23="W",1-$F$25^(T$5-1),$F$25^(T$5-1)) -> 0.034230759 | U23: =IF($I23="W",1-$B$25^(U$5-1),$B$25^(U$5-1))*IF($J23="W",1-$C$25^(U$5-1),$C$25^(U$5-1))*IF($K23="W",1-$D$25^(U$5-1),$D$25^(U$5-1))*IF($L23="W",1-$E$25^(U$5-1),$E$25^(U$5-1))*IF($M23="W",1-$F$25^(U$5-1),$F$25^(U$5-1)) -> 0.034772824 | ... W23: =IF($I23="W",1-$B$25^(W$5-1),$B$25^(W$5-1))*IF($J23="W",1-$C$25^(W$5-1),$C$25^(W$5-1))*IF($K23="W",1-$D$25^(W$5-1),$D$25^(W$5-1))*IF($L23="W",1-$E$25^(W$5-1),$E$25^(W$5-1))*IF($M23="W",1-$F$25^(W$5-1),$F$25^(W$5-1)) -> 0.032110066
A24: 黏住率 | B24: =COUNTIF(B$6:B$21,"WILD")/COUNTA(B$6:B$21) -> 0.0625 | C24: =COUNTIF(C$6:C$21,"WILD")/COUNTA(C$6:C$21) -> 0.066666667 | D24: =COUNTIF(D$6:D$21,"WILD")/COUNTA(D$6:D$21) -> 0.071428571 | E24: =COUNTIF(E$6:E$21,"WILD")/COUNTA(E$6:E$21) -> 0.076923077 | F24: =COUNTIF(F$6:F$21,"WILD")/COUNTA(F$6:F$21) -> 0.083333333 | H24: 18 | I24: W | L24: W | N24: =IF($I24="W",1-$B$25^(N$5-1),$B$25^(N$5-1))*IF($J24="W",1-$C$25^(N$5-1),$C$25^(N$5-1))*IF($K24="W",1-$D$25^(N$5-1),$D$25^(N$5-1))*IF($L24="W",1-$E$25^(N$5-1),$E$25^(N$5-1))*IF($M24="W",1-$F$25^(N$5-1),$F$25^(N$5-1)) -> 0 | O24: =IF($I24="W",1-$B$25^(O$5-1),$B$25^(O$5-1))*IF($J24="W",1-$C$25^(O$5-1),$C$25^(O$5-1))*IF($K24="W",1-$D$25^(O$5-1),$D$25^(O$5-1))*IF($L24="W",1-$E$25^(O$5-1),$E$25^(O$5-1))*IF($M24="W",1-$F$25^(O$5-1),$F$25^(O$5-1)) -> 0.0038194444 | P24: =IF($I24="W",1-$B$25^(P$5-1),$B$25^(P$5-1))*IF($J24="W",1-$C$25^(P$5-1),$C$25^(P$5-1))*IF($K24="W",1-$D$25^(P$5-1),$D$25^(P$5-1))*IF($L24="W",1-$E$25^(P$5-1),$E$25^(P$5-1))*IF($M24="W",1-$F$25^(P$5-1),$F$25^(P$5-1)) -> 0.011305821 | Q24: =IF($I24="W",1-$B$25^(Q$5-1),$B$25^(Q$5-1))*IF($J24="W",1-$C$25^(Q$5-1),$C$25^(Q$5-1))*IF($K24="W",1-$D$25^(Q$5-1),$D$25^(Q$5-1))*IF($L24="W",1-$E$25^(Q$5-1),$E$25^(Q$5-1))*IF($M24="W",1-$F$25^(Q$5-1),$F$25^(Q$5-1)) -> 0.018841206 | R24: =IF($I24="W",1-$B$25^(R$5-1),$B$25^(R$5-1))*IF($J24="W",1-$C$25^(R$5-1),$C$25^(R$5-1))*IF($K24="W",1-$D$25^(R$5-1),$D$25^(R$5-1))*IF($L24="W",1-$E$25^(R$5-1),$E$25^(R$5-1))*IF($M24="W",1-$F$25^(R$5-1),$F$25^(R$5-1)) -> 0.024830868 | S24: =IF($I24="W",1-$B$25^(S$5-1),$B$25^(S$5-1))*IF($J24="W",1-$C$25^(S$5-1),$C$25^(S$5-1))*IF($K24="W",1-$D$25^(S$5-1),$D$25^(S$5-1))*IF($L24="W",1-$E$25^(S$5-1),$E$25^(S$5-1))*IF($M24="W",1-$F$25^(S$5-1),$F$25^(S$5-1)) -> 0.028787144 | T24: =IF($I24="W",1-$B$25^(T$5-1),$B$25^(T$5-1))*IF($J24="W",1-$C$25^(T$5-1),$C$25^(T$5-1))*IF($K24="W",1-$D$25^(T$5-1),$D$25^(T$5-1))*IF($L24="W",1-$E$25^(T$5-1),$E$25^(T$5-1))*IF($M24="W",1-$F$25^(T$5-1),$F$25^(T$5-1)) -> 0.030784187 | U24: =IF($I24="W",1-$B$25^(U$5-1),$B$25^(U$5-1))*IF($J24="W",1-$C$25^(U$5-1),$C$25^(U$5-1))*IF($K24="W",1-$D$25^(U$5-1),$D$25^(U$5-1))*IF($L24="W",1-$E$25^(U$5-1),$E$25^(U$5-1))*IF($M24="W",1-$F$25^(U$5-1),$F$25^(U$5-1)) -> 0.031143449 | ... W24: =IF($I24="W",1-$B$25^(W$5-1),$B$25^(W$5-1))*IF($J24="W",1-$C$25^(W$5-1),$C$25^(W$5-1))*IF($K24="W",1-$D$25^(W$5-1),$D$25^(W$5-1))*IF($L24="W",1-$E$25^(W$5-1),$E$25^(W$5-1))*IF($M24="W",1-$F$25^(W$5-1),$F$25^(W$5-1)) -> 0.028515266
A25: 沒黏住率 q | B25: =1-B24 -> 0.9375 | C25: =1-C24 -> 0.93333333 | D25: =1-D24 -> 0.92857143 | E25: =1-E24 -> 0.92307692 | F25: =1-F24 -> 0.91666667 | H25: 19 | I25: W | L25: W | M25: W | N25: =IF($I25="W",1-$B$25^(N$5-1),$B$25^(N$5-1))*IF($J25="W",1-$C$25^(N$5-1),$C$25^(N$5-1))*IF($K25="W",1-$D$25^(N$5-1),$D$25^(N$5-1))*IF($L25="W",1-$E$25^(N$5-1),$E$25^(N$5-1))*IF($M25="W",1-$F$25^(N$5-1),$F$25^(N$5-1)) -> 0 | O25: =IF($I25="W",1-$B$25^(O$5-1),$B$25^(O$5-1))*IF($J25="W",1-$C$25^(O$5-1),$C$25^(O$5-1))*IF($K25="W",1-$D$25^(O$5-1),$D$25^(O$5-1))*IF($L25="W",1-$E$25^(O$5-1),$E$25^(O$5-1))*IF($M25="W",1-$F$25^(O$5-1),$F$25^(O$5-1)) -> 0.00034722222 | P25: =IF($I25="W",1-$B$25^(P$5-1),$B$25^(P$5-1))*IF($J25="W",1-$C$25^(P$5-1),$C$25^(P$5-1))*IF($K25="W",1-$D$25^(P$5-1),$D$25^(P$5-1))*IF($L25="W",1-$E$25^(P$5-1),$E$25^(P$5-1))*IF($M25="W",1-$F$25^(P$5-1),$F$25^(P$5-1)) -> 0.0021490403 | Q25: =IF($I25="W",1-$B$25^(Q$5-1),$B$25^(Q$5-1))*IF($J25="W",1-$C$25^(Q$5-1),$C$25^(Q$5-1))*IF($K25="W",1-$D$25^(Q$5-1),$D$25^(Q$5-1))*IF($L25="W",1-$E$25^(Q$5-1),$E$25^(Q$5-1))*IF($M25="W",1-$F$25^(Q$5-1),$F$25^(Q$5-1)) -> 0.0056198038 | R25: =IF($I25="W",1-$B$25^(R$5-1),$B$25^(R$5-1))*IF($J25="W",1-$C$25^(R$5-1),$C$25^(R$5-1))*IF($K25="W",1-$D$25^(R$5-1),$D$25^(R$5-1))*IF($L25="W",1-$E$25^(R$5-1),$E$25^(R$5-1))*IF($M25="W",1-$F$25^(R$5-1),$F$25^(R$5-1)) -> 0.010337009 | S25: =IF($I25="W",1-$B$25^(S$5-1),$B$25^(S$5-1))*IF($J25="W",1-$C$25^(S$5-1),$C$25^(S$5-1))*IF($K25="W",1-$D$25^(S$5-1),$D$25^(S$5-1))*IF($L25="W",1-$E$25^(S$5-1),$E$25^(S$5-1))*IF($M25="W",1-$F$25^(S$5-1),$F$25^(S$5-1)) -> 0.01569046 | T25: =IF($I25="W",1-$B$25^(T$5-1),$B$25^(T$5-1))*IF($J25="W",1-$C$25^(T$5-1),$C$25^(T$5-1))*IF($K25="W",1-$D$25^(T$5-1),$D$25^(T$5-1))*IF($L25="W",1-$E$25^(T$5-1),$E$25^(T$5-1))*IF($M25="W",1-$F$25^(T$5-1),$F$25^(T$5-1)) -> 0.021102872 | U25: =IF($I25="W",1-$B$25^(U$5-1),$B$25^(U$5-1))*IF($J25="W",1-$C$25^(U$5-1),$C$25^(U$5-1))*IF($K25="W",1-$D$25^(U$5-1),$D$25^(U$5-1))*IF($L25="W",1-$E$25^(U$5-1),$E$25^(U$5-1))*IF($M25="W",1-$F$25^(U$5-1),$F$25^(U$5-1)) -> 0.026121204 | ... W25: =IF($I25="W",1-$B$25^(W$5-1),$B$25^(W$5-1))*IF($J25="W",1-$C$25^(W$5-1),$C$25^(W$5-1))*IF($K25="W",1-$D$25^(W$5-1),$D$25^(W$5-1))*IF($L25="W",1-$E$25^(W$5-1),$E$25^(W$5-1))*IF($M25="W",1-$F$25^(W$5-1),$F$25^(W$5-1)) -> 0.033883281
H26: 20 | I26: W | K26: W | N26: =IF($I26="W",1-$B$25^(N$5-1),$B$25^(N$5-1))*IF($J26="W",1-$C$25^(N$5-1),$C$25^(N$5-1))*IF($K26="W",1-$D$25^(N$5-1),$D$25^(N$5-1))*IF($L26="W",1-$E$25^(N$5-1),$E$25^(N$5-1))*IF($M26="W",1-$F$25^(N$5-1),$F$25^(N$5-1)) -> 0 | O26: =IF($I26="W",1-$B$25^(O$5-1),$B$25^(O$5-1))*IF($J26="W",1-$C$25^(O$5-1),$C$25^(O$5-1))*IF($K26="W",1-$D$25^(O$5-1),$D$25^(O$5-1))*IF($L26="W",1-$E$25^(O$5-1),$E$25^(O$5-1))*IF($M26="W",1-$F$25^(O$5-1),$F$25^(O$5-1)) -> 0.003525641 | P26: =IF($I26="W",1-$B$25^(P$5-1),$B$25^(P$5-1))*IF($J26="W",1-$C$25^(P$5-1),$C$25^(P$5-1))*IF($K26="W",1-$D$25^(P$5-1),$D$25^(P$5-1))*IF($L26="W",1-$E$25^(P$5-1),$E$25^(P$5-1))*IF($M26="W",1-$F$25^(P$5-1),$F$25^(P$5-1)) -> 0.010404031 | Q26: =IF($I26="W",1-$B$25^(Q$5-1),$B$25^(Q$5-1))*IF($J26="W",1-$C$25^(Q$5-1),$C$25^(Q$5-1))*IF($K26="W",1-$D$25^(Q$5-1),$D$25^(Q$5-1))*IF($L26="W",1-$E$25^(Q$5-1),$E$25^(Q$5-1))*IF($M26="W",1-$F$25^(Q$5-1),$F$25^(Q$5-1)) -> 0.017283706 | R26: =IF($I26="W",1-$B$25^(R$5-1),$B$25^(R$5-1))*IF($J26="W",1-$C$25^(R$5-1),$C$25^(R$5-1))*IF($K26="W",1-$D$25^(R$5-1),$D$25^(R$5-1))*IF($L26="W",1-$E$25^(R$5-1),$E$25^(R$5-1))*IF($M26="W",1-$F$25^(R$5-1),$F$25^(R$5-1)) -> 0.0227047 | S26: =IF($I26="W",1-$B$25^(S$5-1),$B$25^(S$5-1))*IF($J26="W",1-$C$25^(S$5-1),$C$25^(S$5-1))*IF($K26="W",1-$D$25^(S$5-1),$D$25^(S$5-1))*IF($L26="W",1-$E$25^(S$5-1),$E$25^(S$5-1))*IF($M26="W",1-$F$25^(S$5-1),$F$25^(S$5-1)) -> 0.026235258 | T26: =IF($I26="W",1-$B$25^(T$5-1),$B$25^(T$5-1))*IF($J26="W",1-$C$25^(T$5-1),$C$25^(T$5-1))*IF($K26="W",1-$D$25^(T$5-1),$D$25^(T$5-1))*IF($L26="W",1-$E$25^(T$5-1),$E$25^(T$5-1))*IF($M26="W",1-$F$25^(T$5-1),$F$25^(T$5-1)) -> 0.027960487 | U26: =IF($I26="W",1-$B$25^(U$5-1),$B$25^(U$5-1))*IF($J26="W",1-$C$25^(U$5-1),$C$25^(U$5-1))*IF($K26="W",1-$D$25^(U$5-1),$D$25^(U$5-1))*IF($L26="W",1-$E$25^(U$5-1),$E$25^(U$5-1))*IF($M26="W",1-$F$25^(U$5-1),$F$25^(U$5-1)) -> 0.028189127 | ... W26: =IF($I26="W",1-$B$25^(W$5-1),$B$25^(W$5-1))*IF($J26="W",1-$C$25^(W$5-1),$C$25^(W$5-1))*IF($K26="W",1-$D$25^(W$5-1),$D$25^(W$5-1))*IF($L26="W",1-$E$25^(W$5-1),$E$25^(W$5-1))*IF($M26="W",1-$F$25^(W$5-1),$F$25^(W$5-1)) -> 0.025626654
H27: 21 | I27: W | K27: W | M27: W | N27: =IF($I27="W",1-$B$25^(N$5-1),$B$25^(N$5-1))*IF($J27="W",1-$C$25^(N$5-1),$C$25^(N$5-1))*IF($K27="W",1-$D$25^(N$5-1),$D$25^(N$5-1))*IF($L27="W",1-$E$25^(N$5-1),$E$25^(N$5-1))*IF($M27="W",1-$F$25^(N$5-1),$F$25^(N$5-1)) -> 0 | O27: =IF($I27="W",1-$B$25^(O$5-1),$B$25^(O$5-1))*IF($J27="W",1-$C$25^(O$5-1),$C$25^(O$5-1))*IF($K27="W",1-$D$25^(O$5-1),$D$25^(O$5-1))*IF($L27="W",1-$E$25^(O$5-1),$E$25^(O$5-1))*IF($M27="W",1-$F$25^(O$5-1),$F$25^(O$5-1)) -> 0.00032051282 | P27: =IF($I27="W",1-$B$25^(P$5-1),$B$25^(P$5-1))*IF($J27="W",1-$C$25^(P$5-1),$C$25^(P$5-1))*IF($K27="W",1-$D$25^(P$5-1),$D$25^(P$5-1))*IF($L27="W",1-$E$25^(P$5-1),$E$25^(P$5-1))*IF($M27="W",1-$F$25^(P$5-1),$F$25^(P$5-1)) -> 0.0019776257 | Q27: =IF($I27="W",1-$B$25^(Q$5-1),$B$25^(Q$5-1))*IF($J27="W",1-$C$25^(Q$5-1),$C$25^(Q$5-1))*IF($K27="W",1-$D$25^(Q$5-1),$D$25^(Q$5-1))*IF($L27="W",1-$E$25^(Q$5-1),$E$25^(Q$5-1))*IF($M27="W",1-$F$25^(Q$5-1),$F$25^(Q$5-1)) -> 0.0051552451 | R27: =IF($I27="W",1-$B$25^(R$5-1),$B$25^(R$5-1))*IF($J27="W",1-$C$25^(R$5-1),$C$25^(R$5-1))*IF($K27="W",1-$D$25^(R$5-1),$D$25^(R$5-1))*IF($L27="W",1-$E$25^(R$5-1),$E$25^(R$5-1))*IF($M27="W",1-$F$25^(R$5-1),$F$25^(R$5-1)) -> 0.0094518916 | S27: =IF($I27="W",1-$B$25^(S$5-1),$B$25^(S$5-1))*IF($J27="W",1-$C$25^(S$5-1),$C$25^(S$5-1))*IF($K27="W",1-$D$25^(S$5-1),$D$25^(S$5-1))*IF($L27="W",1-$E$25^(S$5-1),$E$25^(S$5-1))*IF($M27="W",1-$F$25^(S$5-1),$F$25^(S$5-1)) -> 0.014299552 | T27: =IF($I27="W",1-$B$25^(T$5-1),$B$25^(T$5-1))*IF($J27="W",1-$C$25^(T$5-1),$C$25^(T$5-1))*IF($K27="W",1-$D$25^(T$5-1),$D$25^(T$5-1))*IF($L27="W",1-$E$25^(T$5-1),$E$25^(T$5-1))*IF($M27="W",1-$F$25^(T$5-1),$F$25^(T$5-1)) -> 0.019167197 | U27: =IF($I27="W",1-$B$25^(U$5-1),$B$25^(U$5-1))*IF($J27="W",1-$C$25^(U$5-1),$C$25^(U$5-1))*IF($K27="W",1-$D$25^(U$5-1),$D$25^(U$5-1))*IF($L27="W",1-$E$25^(U$5-1),$E$25^(U$5-1))*IF($M27="W",1-$F$25^(U$5-1),$F$25^(U$5-1)) -> 0.023643301 | ... W27: =IF($I27="W",1-$B$25^(W$5-1),$B$25^(W$5-1))*IF($J27="W",1-$C$25^(W$5-1),$C$25^(W$5-1))*IF($K27="W",1-$D$25^(W$5-1),$D$25^(W$5-1))*IF($L27="W",1-$E$25^(W$5-1),$E$25^(W$5-1))*IF($M27="W",1-$F$25^(W$5-1),$F$25^(W$5-1)) -> 0.030450886
H28: 22 | I28: W | K28: W | L28: W | N28: =IF($I28="W",1-$B$25^(N$5-1),$B$25^(N$5-1))*IF($J28="W",1-$C$25^(N$5-1),$C$25^(N$5-1))*IF($K28="W",1-$D$25^(N$5-1),$D$25^(N$5-1))*IF($L28="W",1-$E$25^(N$5-1),$E$25^(N$5-1))*IF($M28="W",1-$F$25^(N$5-1),$F$25^(N$5-1)) -> 0 | O28: =IF($I28="W",1-$B$25^(O$5-1),$B$25^(O$5-1))*IF($J28="W",1-$C$25^(O$5-1),$C$25^(O$5-1))*IF($K28="W",1-$D$25^(O$5-1),$D$25^(O$5-1))*IF($L28="W",1-$E$25^(O$5-1),$E$25^(O$5-1))*IF($M28="W",1-$F$25^(O$5-1),$F$25^(O$5-1)) -> 0.00029380342 | P28: =IF($I28="W",1-$B$25^(P$5-1),$B$25^(P$5-1))*IF($J28="W",1-$C$25^(P$5-1),$C$25^(P$5-1))*IF($K28="W",1-$D$25^(P$5-1),$D$25^(P$5-1))*IF($L28="W",1-$E$25^(P$5-1),$E$25^(P$5-1))*IF($M28="W",1-$F$25^(P$5-1),$F$25^(P$5-1)) -> 0.0018062554 | Q28: =IF($I28="W",1-$B$25^(Q$5-1),$B$25^(Q$5-1))*IF($J28="W",1-$C$25^(Q$5-1),$C$25^(Q$5-1))*IF($K28="W",1-$D$25^(Q$5-1),$D$25^(Q$5-1))*IF($L28="W",1-$E$25^(Q$5-1),$E$25^(Q$5-1))*IF($M28="W",1-$F$25^(Q$5-1),$F$25^(Q$5-1)) -> 0.0046910058 | R28: =IF($I28="W",1-$B$25^(R$5-1),$B$25^(R$5-1))*IF($J28="W",1-$C$25^(R$5-1),$C$25^(R$5-1))*IF($K28="W",1-$D$25^(R$5-1),$D$25^(R$5-1))*IF($L28="W",1-$E$25^(R$5-1),$E$25^(R$5-1))*IF($M28="W",1-$F$25^(R$5-1),$F$25^(R$5-1)) -> 0.0085679145 | S28: =IF($I28="W",1-$B$25^(S$5-1),$B$25^(S$5-1))*IF($J28="W",1-$C$25^(S$5-1),$C$25^(S$5-1))*IF($K28="W",1-$D$25^(S$5-1),$D$25^(S$5-1))*IF($L28="W",1-$E$25^(S$5-1),$E$25^(S$5-1))*IF($M28="W",1-$F$25^(S$5-1),$F$25^(S$5-1)) -> 0.012911506 | T28: =IF($I28="W",1-$B$25^(T$5-1),$B$25^(T$5-1))*IF($J28="W",1-$C$25^(T$5-1),$C$25^(T$5-1))*IF($K28="W",1-$D$25^(T$5-1),$D$25^(T$5-1))*IF($L28="W",1-$E$25^(T$5-1),$E$25^(T$5-1))*IF($M28="W",1-$F$25^(T$5-1),$F$25^(T$5-1)) -> 0.01723732 | U28: =IF($I28="W",1-$B$25^(U$5-1),$B$25^(U$5-1))*IF($J28="W",1-$C$25^(U$5-1),$C$25^(U$5-1))*IF($K28="W",1-$D$25^(U$5-1),$D$25^(U$5-1))*IF($L28="W",1-$E$25^(U$5-1),$E$25^(U$5-1))*IF($M28="W",1-$F$25^(U$5-1),$F$25^(U$5-1)) -> 0.021175558 | ... W28: =IF($I28="W",1-$B$25^(W$5-1),$B$25^(W$5-1))*IF($J28="W",1-$C$25^(W$5-1),$C$25^(W$5-1))*IF($K28="W",1-$D$25^(W$5-1),$D$25^(W$5-1))*IF($L28="W",1-$E$25^(W$5-1),$E$25^(W$5-1))*IF($M28="W",1-$F$25^(W$5-1),$F$25^(W$5-1)) -> 0.027041835
H29: 23 | I29: W | K29: W | L29: W | M29: W | N29: =IF($I29="W",1-$B$25^(N$5-1),$B$25^(N$5-1))*IF($J29="W",1-$C$25^(N$5-1),$C$25^(N$5-1))*IF($K29="W",1-$D$25^(N$5-1),$D$25^(N$5-1))*IF($L29="W",1-$E$25^(N$5-1),$E$25^(N$5-1))*IF($M29="W",1-$F$25^(N$5-1),$F$25^(N$5-1)) -> 0 | O29: =IF($I29="W",1-$B$25^(O$5-1),$B$25^(O$5-1))*IF($J29="W",1-$C$25^(O$5-1),$C$25^(O$5-1))*IF($K29="W",1-$D$25^(O$5-1),$D$25^(O$5-1))*IF($L29="W",1-$E$25^(O$5-1),$E$25^(O$5-1))*IF($M29="W",1-$F$25^(O$5-1),$F$25^(O$5-1)) -> 2.6709402e-05 | P29: =IF($I29="W",1-$B$25^(P$5-1),$B$25^(P$5-1))*IF($J29="W",1-$C$25^(P$5-1),$C$25^(P$5-1))*IF($K29="W",1-$D$25^(P$5-1),$D$25^(P$5-1))*IF($L29="W",1-$E$25^(P$5-1),$E$25^(P$5-1))*IF($M29="W",1-$F$25^(P$5-1),$F$25^(P$5-1)) -> 0.0003433378 | Q29: =IF($I29="W",1-$B$25^(Q$5-1),$B$25^(Q$5-1))*IF($J29="W",1-$C$25^(Q$5-1),$C$25^(Q$5-1))*IF($K29="W",1-$D$25^(Q$5-1),$D$25^(Q$5-1))*IF($L29="W",1-$E$25^(Q$5-1),$E$25^(Q$5-1))*IF($M29="W",1-$F$25^(Q$5-1),$F$25^(Q$5-1)) -> 0.0013991956 | R29: =IF($I29="W",1-$B$25^(R$5-1),$B$25^(R$5-1))*IF($J29="W",1-$C$25^(R$5-1),$C$25^(R$5-1))*IF($K29="W",1-$D$25^(R$5-1),$D$25^(R$5-1))*IF($L29="W",1-$E$25^(R$5-1),$E$25^(R$5-1))*IF($M29="W",1-$F$25^(R$5-1),$F$25^(R$5-1)) -> 0.0035667946 | S29: =IF($I29="W",1-$B$25^(S$5-1),$B$25^(S$5-1))*IF($J29="W",1-$C$25^(S$5-1),$C$25^(S$5-1))*IF($K29="W",1-$D$25^(S$5-1),$D$25^(S$5-1))*IF($L29="W",1-$E$25^(S$5-1),$E$25^(S$5-1))*IF($M29="W",1-$F$25^(S$5-1),$F$25^(S$5-1)) -> 0.0070374287 | T29: =IF($I29="W",1-$B$25^(T$5-1),$B$25^(T$5-1))*IF($J29="W",1-$C$25^(T$5-1),$C$25^(T$5-1))*IF($K29="W",1-$D$25^(T$5-1),$D$25^(T$5-1))*IF($L29="W",1-$E$25^(T$5-1),$E$25^(T$5-1))*IF($M29="W",1-$F$25^(T$5-1),$F$25^(T$5-1)) -> 0.011816358 | U29: =IF($I29="W",1-$B$25^(U$5-1),$B$25^(U$5-1))*IF($J29="W",1-$C$25^(U$5-1),$C$25^(U$5-1))*IF($K29="W",1-$D$25^(U$5-1),$D$25^(U$5-1))*IF($L29="W",1-$E$25^(U$5-1),$E$25^(U$5-1))*IF($M29="W",1-$F$25^(U$5-1),$F$25^(U$5-1)) -> 0.017760752 | ... W29: =IF($I29="W",1-$B$25^(W$5-1),$B$25^(W$5-1))*IF($J29="W",1-$C$25^(W$5-1),$C$25^(W$5-1))*IF($K29="W",1-$D$25^(W$5-1),$D$25^(W$5-1))*IF($L29="W",1-$E$25^(W$5-1),$E$25^(W$5-1))*IF($M29="W",1-$F$25^(W$5-1),$F$25^(W$5-1)) -> 0.032132476
H30: 24 | I30: W | J30: W | N30: =IF($I30="W",1-$B$25^(N$5-1),$B$25^(N$5-1))*IF($J30="W",1-$C$25^(N$5-1),$C$25^(N$5-1))*IF($K30="W",1-$D$25^(N$5-1),$D$25^(N$5-1))*IF($L30="W",1-$E$25^(N$5-1),$E$25^(N$5-1))*IF($M30="W",1-$F$25^(N$5-1),$F$25^(N$5-1)) -> 0 | O30: =IF($I30="W",1-$B$25^(O$5-1),$B$25^(O$5-1))*IF($J30="W",1-$C$25^(O$5-1),$C$25^(O$5-1))*IF($K30="W",1-$D$25^(O$5-1),$D$25^(O$5-1))*IF($L30="W",1-$E$25^(O$5-1),$E$25^(O$5-1))*IF($M30="W",1-$F$25^(O$5-1),$F$25^(O$5-1)) -> 0.0032738095 | P30: =IF($I30="W",1-$B$25^(P$5-1),$B$25^(P$5-1))*IF($J30="W",1-$C$25^(P$5-1),$C$25^(P$5-1))*IF($K30="W",1-$D$25^(P$5-1),$D$25^(P$5-1))*IF($L30="W",1-$E$25^(P$5-1),$E$25^(P$5-1))*IF($M30="W",1-$F$25^(P$5-1),$F$25^(P$5-1)) -> 0.0096353281 | Q30: =IF($I30="W",1-$B$25^(Q$5-1),$B$25^(Q$5-1))*IF($J30="W",1-$C$25^(Q$5-1),$C$25^(Q$5-1))*IF($K30="W",1-$D$25^(Q$5-1),$D$25^(Q$5-1))*IF($L30="W",1-$E$25^(Q$5-1),$E$25^(Q$5-1))*IF($M30="W",1-$F$25^(Q$5-1),$F$25^(Q$5-1)) -> 0.01596338 | R30: =IF($I30="W",1-$B$25^(R$5-1),$B$25^(R$5-1))*IF($J30="W",1-$C$25^(R$5-1),$C$25^(R$5-1))*IF($K30="W",1-$D$25^(R$5-1),$D$25^(R$5-1))*IF($L30="W",1-$E$25^(R$5-1),$E$25^(R$5-1))*IF($M30="W",1-$F$25^(R$5-1),$F$25^(R$5-1)) -> 0.020912237 | S30: =IF($I30="W",1-$B$25^(S$5-1),$B$25^(S$5-1))*IF($J30="W",1-$C$25^(S$5-1),$C$25^(S$5-1))*IF($K30="W",1-$D$25^(S$5-1),$D$25^(S$5-1))*IF($L30="W",1-$E$25^(S$5-1),$E$25^(S$5-1))*IF($M30="W",1-$F$25^(S$5-1),$F$25^(S$5-1)) -> 0.024095755 | T30: =IF($I30="W",1-$B$25^(T$5-1),$B$25^(T$5-1))*IF($J30="W",1-$C$25^(T$5-1),$C$25^(T$5-1))*IF($K30="W",1-$D$25^(T$5-1),$D$25^(T$5-1))*IF($L30="W",1-$E$25^(T$5-1),$E$25^(T$5-1))*IF($M30="W",1-$F$25^(T$5-1),$F$25^(T$5-1)) -> 0.025606149 | U30: =IF($I30="W",1-$B$25^(U$5-1),$B$25^(U$5-1))*IF($J30="W",1-$C$25^(U$5-1),$C$25^(U$5-1))*IF($K30="W",1-$D$25^(U$5-1),$D$25^(U$5-1))*IF($L30="W",1-$E$25^(U$5-1),$E$25^(U$5-1))*IF($M30="W",1-$F$25^(U$5-1),$F$25^(U$5-1)) -> 0.025739463 | ... W30: =IF($I30="W",1-$B$25^(W$5-1),$B$25^(W$5-1))*IF($J30="W",1-$C$25^(W$5-1),$C$25^(W$5-1))*IF($K30="W",1-$D$25^(W$5-1),$D$25^(W$5-1))*IF($L30="W",1-$E$25^(W$5-1),$E$25^(W$5-1))*IF($M30="W",1-$F$25^(W$5-1),$F$25^(W$5-1)) -> 0.023257825
H31: 25 | I31: W | J31: W | M31: W | N31: =IF($I31="W",1-$B$25^(N$5-1),$B$25^(N$5-1))*IF($J31="W",1-$C$25^(N$5-1),$C$25^(N$5-1))*IF($K31="W",1-$D$25^(N$5-1),$D$25^(N$5-1))*IF($L31="W",1-$E$25^(N$5-1),$E$25^(N$5-1))*IF($M31="W",1-$F$25^(N$5-1),$F$25^(N$5-1)) -> 0 | O31: =IF($I31="W",1-$B$25^(O$5-1),$B$25^(O$5-1))*IF($J31="W",1-$C$25^(O$5-1),$C$25^(O$5-1))*IF($K31="W",1-$D$25^(O$5-1),$D$25^(O$5-1))*IF($L31="W",1-$E$25^(O$5-1),$E$25^(O$5-1))*IF($M31="W",1-$F$25^(O$5-1),$F$25^(O$5-1)) -> 0.00029761905 | P31: =IF($I31="W",1-$B$25^(P$5-1),$B$25^(P$5-1))*IF($J31="W",1-$C$25^(P$5-1),$C$25^(P$5-1))*IF($K31="W",1-$D$25^(P$5-1),$D$25^(P$5-1))*IF($L31="W",1-$E$25^(P$5-1),$E$25^(P$5-1))*IF($M31="W",1-$F$25^(P$5-1),$F$25^(P$5-1)) -> 0.0018315086 | Q31: =IF($I31="W",1-$B$25^(Q$5-1),$B$25^(Q$5-1))*IF($J31="W",1-$C$25^(Q$5-1),$C$25^(Q$5-1))*IF($K31="W",1-$D$25^(Q$5-1),$D$25^(Q$5-1))*IF($L31="W",1-$E$25^(Q$5-1),$E$25^(Q$5-1))*IF($M31="W",1-$F$25^(Q$5-1),$F$25^(Q$5-1)) -> 0.0047614288 | R31: =IF($I31="W",1-$B$25^(R$5-1),$B$25^(R$5-1))*IF($J31="W",1-$C$25^(R$5-1),$C$25^(R$5-1))*IF($K31="W",1-$D$25^(R$5-1),$D$25^(R$5-1))*IF($L31="W",1-$E$25^(R$5-1),$E$25^(R$5-1))*IF($M31="W",1-$F$25^(R$5-1),$F$25^(R$5-1)) -> 0.0087056953 | S31: =IF($I31="W",1-$B$25^(S$5-1),$B$25^(S$5-1))*IF($J31="W",1-$C$25^(S$5-1),$C$25^(S$5-1))*IF($K31="W",1-$D$25^(S$5-1),$D$25^(S$5-1))*IF($L31="W",1-$E$25^(S$5-1),$E$25^(S$5-1))*IF($M31="W",1-$F$25^(S$5-1),$F$25^(S$5-1)) -> 0.013133414 | T31: =IF($I31="W",1-$B$25^(T$5-1),$B$25^(T$5-1))*IF($J31="W",1-$C$25^(T$5-1),$C$25^(T$5-1))*IF($K31="W",1-$D$25^(T$5-1),$D$25^(T$5-1))*IF($L31="W",1-$E$25^(T$5-1),$E$25^(T$5-1))*IF($M31="W",1-$F$25^(T$5-1),$F$25^(T$5-1)) -> 0.017553274 | U31: =IF($I31="W",1-$B$25^(U$5-1),$B$25^(U$5-1))*IF($J31="W",1-$C$25^(U$5-1),$C$25^(U$5-1))*IF($K31="W",1-$D$25^(U$5-1),$D$25^(U$5-1))*IF($L31="W",1-$E$25^(U$5-1),$E$25^(U$5-1))*IF($M31="W",1-$F$25^(U$5-1),$F$25^(U$5-1)) -> 0.021588674 | ... W31: =IF($I31="W",1-$B$25^(W$5-1),$B$25^(W$5-1))*IF($J31="W",1-$C$25^(W$5-1),$C$25^(W$5-1))*IF($K31="W",1-$D$25^(W$5-1),$D$25^(W$5-1))*IF($L31="W",1-$E$25^(W$5-1),$E$25^(W$5-1))*IF($M31="W",1-$F$25^(W$5-1),$F$25^(W$5-1)) -> 0.027636123
H32: 26 | I32: W | J32: W | L32: W | N32: =IF($I32="W",1-$B$25^(N$5-1),$B$25^(N$5-1))*IF($J32="W",1-$C$25^(N$5-1),$C$25^(N$5-1))*IF($K32="W",1-$D$25^(N$5-1),$D$25^(N$5-1))*IF($L32="W",1-$E$25^(N$5-1),$E$25^(N$5-1))*IF($M32="W",1-$F$25^(N$5-1),$F$25^(N$5-1)) -> 0 | O32: =IF($I32="W",1-$B$25^(O$5-1),$B$25^(O$5-1))*IF($J32="W",1-$C$25^(O$5-1),$C$25^(O$5-1))*IF($K32="W",1-$D$25^(O$5-1),$D$25^(O$5-1))*IF($L32="W",1-$E$25^(O$5-1),$E$25^(O$5-1))*IF($M32="W",1-$F$25^(O$5-1),$F$25^(O$5-1)) -> 0.00027281746 | P32: =IF($I32="W",1-$B$25^(P$5-1),$B$25^(P$5-1))*IF($J32="W",1-$C$25^(P$5-1),$C$25^(P$5-1))*IF($K32="W",1-$D$25^(P$5-1),$D$25^(P$5-1))*IF($L32="W",1-$E$25^(P$5-1),$E$25^(P$5-1))*IF($M32="W",1-$F$25^(P$5-1),$F$25^(P$5-1)) -> 0.0016728 | Q32: =IF($I32="W",1-$B$25^(Q$5-1),$B$25^(Q$5-1))*IF($J32="W",1-$C$25^(Q$5-1),$C$25^(Q$5-1))*IF($K32="W",1-$D$25^(Q$5-1),$D$25^(Q$5-1))*IF($L32="W",1-$E$25^(Q$5-1),$E$25^(Q$5-1))*IF($M32="W",1-$F$25^(Q$5-1),$F$25^(Q$5-1)) -> 0.0043326534 | R32: =IF($I32="W",1-$B$25^(R$5-1),$B$25^(R$5-1))*IF($J32="W",1-$C$25^(R$5-1),$C$25^(R$5-1))*IF($K32="W",1-$D$25^(R$5-1),$D$25^(R$5-1))*IF($L32="W",1-$E$25^(R$5-1),$E$25^(R$5-1))*IF($M32="W",1-$F$25^(R$5-1),$F$25^(R$5-1)) -> 0.0078915054 | S32: =IF($I32="W",1-$B$25^(S$5-1),$B$25^(S$5-1))*IF($J32="W",1-$C$25^(S$5-1),$C$25^(S$5-1))*IF($K32="W",1-$D$25^(S$5-1),$D$25^(S$5-1))*IF($L32="W",1-$E$25^(S$5-1),$E$25^(S$5-1))*IF($M32="W",1-$F$25^(S$5-1),$F$25^(S$5-1)) -> 0.011858564 | T32: =IF($I32="W",1-$B$25^(T$5-1),$B$25^(T$5-1))*IF($J32="W",1-$C$25^(T$5-1),$C$25^(T$5-1))*IF($K32="W",1-$D$25^(T$5-1),$D$25^(T$5-1))*IF($L32="W",1-$E$25^(T$5-1),$E$25^(T$5-1))*IF($M32="W",1-$F$25^(T$5-1),$F$25^(T$5-1)) -> 0.015785898 | U32: =IF($I32="W",1-$B$25^(U$5-1),$B$25^(U$5-1))*IF($J32="W",1-$C$25^(U$5-1),$C$25^(U$5-1))*IF($K32="W",1-$D$25^(U$5-1),$D$25^(U$5-1))*IF($L32="W",1-$E$25^(U$5-1),$E$25^(U$5-1))*IF($M32="W",1-$F$25^(U$5-1),$F$25^(U$5-1)) -> 0.01933538 | ... W32: =IF($I32="W",1-$B$25^(W$5-1),$B$25^(W$5-1))*IF($J32="W",1-$C$25^(W$5-1),$C$25^(W$5-1))*IF($K32="W",1-$D$25^(W$5-1),$D$25^(W$5-1))*IF($L32="W",1-$E$25^(W$5-1),$E$25^(W$5-1))*IF($M32="W",1-$F$25^(W$5-1),$F$25^(W$5-1)) -> 0.024542192
